Workbook

Sheet Introduction
A1: Welcome to the ELO Mafia Rankings Leaderboard!
A3: How to use this sheet: Start with the Stats Summary tab. This will give you your win rates, your 'sigma' and 'mu' (see FAQ) and, most importantly, your Elo. The FAQ explains how the ratings are calculated, among other things, so if you want to figure out how to reverse engineer everything head over there to take a look. The MatchHistory tab shows how your stats are calculated on a game-by-game basis. The MafiaRatings tab is where we calculate your 'sigma' and 'mu', but probably isn't terribly useful unless you're really interested in getting down into the fine details.
A12: FAQ
A19: If you find an error, like two rankings for the same player, etc., tell Brown Kow in Discord

Sheet Stats Summary
A1: Name | B1: Town Games | C1: Town Wins | D1: Town Win % | E1: Mafia Games | F1: Mafia Wins | G1: Mafia Win % | H1: Total Games | I1: Total Win % | J1: Mu | K1: Sigma | L1: Rating
A2: Rocker | B2: =COUNTIFS(MatchHistory!$B:$B, $A2, MatchHistory!$C:$C, "Town") -> 68 | C2: =COUNTIFS(MatchHistory!B:B, A2, MatchHistory!C:C, "Town", MatchHistory!D:D, "Win") -> 31 | D2: =IFERROR(__xludf.DUMMYFUNCTION("IF(EQ($B2, 0), TO_PERCENT(0), TO_PERCENT($C2/$B2))"),0.45588235294117646) -> 0.45588235 | E2: =COUNTIFS(MatchHistory!$B:$B, $A2, MatchHistory!$C:$C, "Mafia") -> 22 | F2: =COUNTIFS(MatchHistory!$B:$B, $A2, MatchHistory!$C:$C, "Mafia", MatchHistory!$D:$D, "Win") -> 16 | G2: =IFERROR(__xludf.DUMMYFUNCTION("TO_PERCENT(IFERROR($F2/$E2, 0))"),0.7272727272727273) -> 0.72727273 | H2: =SUM(E2, B2) -> 90 | I2: =IFERROR(__xludf.DUMMYFUNCTION("TO_PERCENT(IFERROR(($F2+$C2)/($E2+$B2), 0))"),0.5222222222222223) -> 0.52222222 | J2: {=INDEX(MatchHistory!$G:$G,MATCH(1,(MatchHistory!$B:$B=$A2)*(MatchHistory!$G:$G<>""),0))} -> 36.736488 | K2: {=INDEX(MatchHistory!$H:$H,MATCH(1,(MatchHistory!$B:$B=$A2)*(MatchHistory!$H:$H<>""),0))} -> 5.3194585 | L2: {=INDEX(MatchHistory!$J:$J,MATCH(1,(MatchHistory!$B:$B=$A2)*(MatchHistory!$J:$J<>""),0))} -> 1955
A3: Laur | B3: =COUNTIFS(MatchHistory!$B:$B, $A3, MatchHistory!$C:$C, "Town") -> 48 | C3: =COUNTIFS(MatchHistory!B:B, A3, MatchHistory!C:C, "Town", MatchHistory!D:D, "Win") -> 23 | D3: =IFERROR(__xludf.DUMMYFUNCTION("IF(EQ($B3, 0), TO_PERCENT(0), TO_PERCENT($C3/$B3))"),0.4791666666666667) -> 0.47916667 | E3: =COUNTIFS(MatchHistory!$B:$B, $A3, MatchHistory!$C:$C, "Mafia") -> 11 | F3: =COUNTIFS(MatchHistory!$B:$B, $A3, MatchHistory!$C:$C, "Mafia", MatchHistory!$D:$D, "Win") -> 8 | G3: =IFERROR(__xludf.DUMMYFUNCTION("TO_PERCENT(IFERROR($F3/$E3, 0))"),0.7272727272727273) -> 0.72727273 | H3: =SUM(E3, B3) -> 59 | I3: =IFERROR(__xludf.DUMMYFUNCTION("TO_PERCENT(IFERROR(($F3+$C3)/($E3+$B3), 0))"),0.5254237288135594) -> 0.52542373 | J3: {=INDEX(MatchHistory!$G:$G,MATCH(1,(MatchHistory!$B:$B=$A3)*(MatchHistory!$G:$G<>""),0))} -> 35.476764 | K3: {=INDEX(MatchHistory!$H:$H,MATCH(1,(MatchHistory!$B:$B=$A3)*(MatchHistory!$H:$H<>""),0))} -> 5.8193791 | L3: {=INDEX(MatchHistory!$J:$J,MATCH(1,(MatchHistory!$B:$B=$A3)*(MatchHistory!$J:$J<>""),0))} -> 1819
A4: Noah | B4: =COUNTIFS(MatchHistory!$B:$B, $A4, MatchHistory!$C:$C, "Town") -> 41 | C4: =COUNTIFS(MatchHistory!B:B, A4, MatchHistory!C:C, "Town", MatchHistory!D:D, "Win") -> 19 | D4: =IFERROR(__xludf.DUMMYFUNCTION("IF(EQ($B4, 0), TO_PERCENT(0), TO_PERCENT($C4/$B4))"),0.4634146341463415) -> 0.46341463 | E4: =COUNTIFS(MatchHistory!$B:$B, $A4, MatchHistory!$C:$C, "Mafia") -> 16 | F4: =COUNTIFS(MatchHistory!$B:$B, $A4, MatchHistory!$C:$C, "Mafia", MatchHistory!$D:$D, "Win") -> 10 | G4: =IFERROR(__xludf.DUMMYFUNCTION("TO_PERCENT(IFERROR($F4/$E4, 0))"),0.625) -> 0.625 | H4: =SUM(E4, B4) -> 57 | I4: =IFERROR(__xludf.DUMMYFUNCTION("TO_PERCENT(IFERROR(($F4+$C4)/($E4+$B4), 0))"),0.5087719298245614) -> 0.50877193 | J4: {=INDEX(MatchHistory!$G:$G,MATCH(1,(MatchHistory!$B:$B=$A4)*(MatchHistory!$G:$G<>""),0))} -> 34.73979 | K4: {=INDEX(MatchHistory!$H:$H,MATCH(1,(MatchHistory!$B:$B=$A4)*(MatchHistory!$H:$H<>""),0))} -> 5.9820323 | L4: {=INDEX(MatchHistory!$J:$J,MATCH(1,(MatchHistory!$B:$B=$A4)*(MatchHistory!$J:$J<>""),0))} -> 1752
A5: Creatchee | B5: =COUNTIFS(MatchHistory!$B:$B, $A5, MatchHistory!$C:$C, "Town") -> 21 | C5: =COUNTIFS(MatchHistory!B:B, A5, MatchHistory!C:C, "Town", MatchHistory!D:D, "Win") -> 15 | D5: =IFERROR(__xludf.DUMMYFUNCTION("IF(EQ($B5, 0), TO_PERCENT(0), TO_PERCENT($C5/$B5))"),0.7142857142857143) -> 0.71428571 | E5: =COUNTIFS(MatchHistory!$B:$B, $A5, MatchHistory!$C:$C, "Mafia") -> 3 | F5: =COUNTIFS(MatchHistory!$B:$B, $A5, MatchHistory!$C:$C, "Mafia", MatchHistory!$D:$D, "Win") -> 2 | G5: =IFERROR(__xludf.DUMMYFUNCTION("TO_PERCENT(IFERROR($F5/$E5, 0))"),0.6666666666666666) -> 0.66666667 | H5: =SUM(E5, B5) -> 24 | I5: =IFERROR(__xludf.DUMMYFUNCTION("TO_PERCENT(IFERROR(($F5+$C5)/($E5+$B5), 0))"),0.7083333333333334) -> 0.70833333 | J5: {=INDEX(MatchHistory!$G:$G,MATCH(1,(MatchHistory!$B:$B=$A5)*(MatchHistory!$G:$G<>""),0))} -> 36.313279 | K5: {=INDEX(MatchHistory!$H:$H,MATCH(1,(MatchHistory!$B:$B=$A5)*(MatchHistory!$H:$H<>""),0))} -> 7.1623727 | L5: {=INDEX(MatchHistory!$J:$J,MATCH(1,(MatchHistory!$B:$B=$A5)*(MatchHistory!$J:$J<>""),0))} -> 1739
A6: Rollo | B6: =COUNTIFS(MatchHistory!$B:$B, $A6, MatchHistory!$C:$C, "Town") -> 23 | C6: =COUNTIFS(MatchHistory!B:B, A6, MatchHistory!C:C, "Town", MatchHistory!D:D, "Win") -> 16 | D6: =IFERROR(__xludf.DUMMYFUNCTION("IF(EQ($B6, 0), TO_PERCENT(0), TO_PERCENT($C6/$B6))"),0.6956521739130435) -> 0.69565217 | E6: =COUNTIFS(MatchHistory!$B:$B, $A6, MatchHistory!$C:$C, "Mafia") -> 9 | F6: =COUNTIFS(MatchHistory!$B:$B, $A6, MatchHistory!$C:$C, "Mafia", MatchHistory!$D:$D, "Win") -> 4 | G6: =IFERROR(__xludf.DUMMYFUNCTION("TO_PERCENT(IFERROR($F6/$E6, 0))"),0.4444444444444444) -> 0.44444444 | H6: =SUM(E6, B6) -> 32 | I6: =IFERROR(__xludf.DUMMYFUNCTION("TO_PERCENT(IFERROR(($F6+$C6)/($E6+$B6), 0))"),0.625) -> 0.625 | J6: {=INDEX(MatchHistory!$G:$G,MATCH(1,(MatchHistory!$B:$B=$A6)*(MatchHistory!$G:$G<>""),0))} -> 35.160791 | K6: {=INDEX(MatchHistory!$H:$H,MATCH(1,(MatchHistory!$B:$B=$A6)*(MatchHistory!$H:$H<>""),0))} -> 6.7721296 | L6: {=INDEX(MatchHistory!$J:$J,MATCH(1,(MatchHistory!$B:$B=$A6)*(MatchHistory!$J:$J<>""),0))} -> 1700
A7: Cyclone | B7: =COUNTIFS(MatchHistory!$B:$B, $A7, MatchHistory!$C:$C, "Town") -> 26 | C7: =COUNTIFS(MatchHistory!B:B, A7, MatchHistory!C:C, "Town", MatchHistory!D:D, "Win") -> 11 | D7: =IFERROR(__xludf.DUMMYFUNCTION("IF(EQ($B7, 0), TO_PERCENT(0), TO_PERCENT($C7/$B7))"),0.4230769230769231) -> 0.42307692 | E7: =COUNTIFS(MatchHistory!$B:$B, $A7, MatchHistory!$C:$C, "Mafia") -> 8 | F7: =COUNTIFS(MatchHistory!$B:$B, $A7, MatchHistory!$C:$C, "Mafia", MatchHistory!$D:$D, "Win") -> 7 | G7: =IFERROR(__xludf.DUMMYFUNCTION("TO_PERCENT(IFERROR($F7/$E7, 0))"),0.875) -> 0.875 | H7: =SUM(E7, B7) -> 34 | I7: =IFERROR(__xludf.DUMMYFUNCTION("TO_PERCENT(IFERROR(($F7+$C7)/($E7+$B7), 0))"),0.5294117647058824) -> 0.52941176 | J7: {=INDEX(MatchHistory!$G:$G,MATCH(1,(MatchHistory!$B:$B=$A7)*(MatchHistory!$G:$G<>""),0))} -> 33.996747 | K7: {=INDEX(MatchHistory!$H:$H,MATCH(1,(MatchHistory!$B:$B=$A7)*(MatchHistory!$H:$H<>""),0))} -> 6.6752051 | L7: {=INDEX(MatchHistory!$J:$J,MATCH(1,(MatchHistory!$B:$B=$A7)*(MatchHistory!$J:$J<>""),0))} -> 1631
A8: Iln | B8: =COUNTIFS(MatchHistory!$B:$B, $A8, MatchHistory!$C:$C, "Town") -> 69 | C8: =COUNTIFS(MatchHistory!B:B, A8, MatchHistory!C:C, "Town", MatchHistory!D:D, "Win") -> 28 | D8: =IFERROR(__xludf.DUMMYFUNCTION("IF(EQ($B8, 0), TO_PERCENT(0), TO_PERCENT($C8/$B8))"),0.4057971014492754) -> 0.4057971 | E8: =COUNTIFS(MatchHistory!$B:$B, $A8, MatchHistory!$C:$C, "Mafia") -> 18 | F8: =COUNTIFS(MatchHistory!$B:$B, $A8, MatchHistory!$C:$C, "Mafia", MatchHistory!$D:$D, "Win") -> 12 | G8: =IFERROR(__xludf.DUMMYFUNCTION("TO_PERCENT(IFERROR($F8/$E8, 0))"),0.6666666666666666) -> 0.66666667 | H8: =SUM(E8, B8) -> 87 | I8: =IFERROR(__xludf.DUMMYFUNCTION("TO_PERCENT(IFERROR(($F8+$C8)/($E8+$B8), 0))"),0.45977011494252873) -> 0.45977011 | J8: {=INDEX(MatchHistory!$G:$G,MATCH(1,(MatchHistory!$B:$B=$A8)*(MatchHistory!$G:$G<>""),0))} -> 31.816797 | K8: {=INDEX(MatchHistory!$H:$H,MATCH(1,(MatchHistory!$B:$B=$A8)*(MatchHistory!$H:$H<>""),0))} -> 5.238906 | L8: {=INDEX(MatchHistory!$J:$J,MATCH(1,(MatchHistory!$B:$B=$A8)*(MatchHistory!$J:$J<>""),0))} -> 1629
A9: Brownkow | B9: =COUNTIFS(MatchHistory!$B:$B, $A9, MatchHistory!$C:$C, "Town") -> 62 | C9: =COUNTIFS(MatchHistory!B:B, A9, MatchHistory!C:C, "Town", MatchHistory!D:D, "Win") -> 30 | D9: =IFERROR(__xludf.DUMMYFUNCTION("IF(EQ($B9, 0), TO_PERCENT(0), TO_PERCENT($C9/$B9))"),0.4838709677419355) -> 0.48387097 | E9: =COUNTIFS(MatchHistory!$B:$B, $A9, MatchHistory!$C:$C, "Mafia") -> 22 | F9: =COUNTIFS(MatchHistory!$B:$B, $A9, MatchHistory!$C:$C, "Mafia", MatchHistory!$D:$D, "Win") -> 12 | G9: =IFERROR(__xludf.DUMMYFUNCTION("TO_PERCENT(IFERROR($F9/$E9, 0))"),0.5454545454545454) -> 0.54545455 | H9: =SUM(E9, B9) -> 84 | I9: =IFERROR(__xludf.DUMMYFUNCTION("TO_PERCENT(IFERROR(($F9+$C9)/($E9+$B9), 0))"),0.5) -> 0.5 | J9: {=INDEX(MatchHistory!$G:$G,MATCH(1,(MatchHistory!$B:$B=$A9)*(MatchHistory!$G:$G<>""),0))} -> 31.363469 | K9: {=INDEX(MatchHistory!$H:$H,MATCH(1,(MatchHistory!$B:$B=$A9)*(MatchHistory!$H:$H<>""),0))} -> 5.3604515 | L9: {=INDEX(MatchHistory!$J:$J,MATCH(1,(MatchHistory!$B:$B=$A9)*(MatchHistory!$J:$J<>""),0))} -> 1586
A10: Chipper | B10: =COUNTIFS(MatchHistory!$B:$B, $A10, MatchHistory!$C:$C, "Town") -> 46 | C10: =COUNTIFS(MatchHistory!B:B, A10, MatchHistory!C:C, "Town", MatchHistory!D:D, "Win") -> 18 | D10: =IFERROR(__xludf.DUMMYFUNCTION("IF(EQ($B10, 0), TO_PERCENT(0), TO_PERCENT($C10/$B10))"),0.391304347826087) -> 0.39130435 | E10: =COUNTIFS(MatchHistory!$B:$B, $A10, MatchHistory!$C:$C, "Mafia") -> 18 | F10: =COUNTIFS(MatchHistory!$B:$B, $A10, MatchHistory!$C:$C, "Mafia", MatchHistory!$D:$D, "Win") -> 12 | G10: =IFERROR(__xludf.DUMMYFUNCTION("TO_PERCENT(IFERROR($F10/$E10, 0))"),0.6666666666666666) -> 0.66666667 | H10: =SUM(E10, B10) -> 64 | I10: =IFERROR(__xludf.DUMMYFUNCTION("TO_PERCENT(IFERROR(($F10+$C10)/($E10+$B10), 0))"),0.46875) -> 0.46875 | J10: {=INDEX(MatchHistory!$G:$G,MATCH(1,(MatchHistory!$B:$B=$A10)*(MatchHistory!$G:$G<>""),0))} -> 31.980698 | K10: {=INDEX(MatchHistory!$H:$H,MATCH(1,(MatchHistory!$B:$B=$A10)*(MatchHistory!$H:$H<>""),0))} -> 5.8149377 | L10: {=INDEX(MatchHistory!$J:$J,MATCH(1,(MatchHistory!$B:$B=$A10)*(MatchHistory!$J:$J<>""),0))} -> 1582
A11: Heckmuffins | B11: =COUNTIFS(MatchHistory!$B:$B, $A11, MatchHistory!$C:$C, "Town") -> 7 | C11: =COUNTIFS(MatchHistory!B:B, A11, MatchHistory!C:C, "Town", MatchHistory!D:D, "Win") -> 5 | D11: =IFERROR(__xludf.DUMMYFUNCTION("IF(EQ($B11, 0), TO_PERCENT(0), TO_PERCENT($C11/$B11))"),0.7142857142857143) -> 0.71428571 | E11: =COUNTIFS(MatchHistory!$B:$B, $A11, MatchHistory!$C:$C, "Mafia") -> 0 | F11: =COUNTIFS(MatchHistory!$B:$B, $A11, MatchHistory!$C:$C, "Mafia", MatchHistory!$D:$D, "Win") -> 0 | G11: =IFERROR(__xludf.DUMMYFUNCTION("TO_PERCENT(IFERROR($F11/$E11, 0))"),0.0) -> 0 | H11: =SUM(E11, B11) -> 7 | I11: =IFERROR(__xludf.DUMMYFUNCTION("TO_PERCENT(IFERROR(($F11+$C11)/($E11+$B11), 0))"),0.7142857142857143) -> 0.71428571 | J11: {=INDEX(MatchHistory!$G:$G,MATCH(1,(MatchHistory!$B:$B=$A11)*(MatchHistory!$G:$G<>""),0))} -> 34.52848 | K11: {=INDEX(MatchHistory!$H:$H,MATCH(1,(MatchHistory!$B:$B=$A11)*(MatchHistory!$H:$H<>""),0))} -> 7.7566785 | L11: {=INDEX(MatchHistory!$J:$J,MATCH(1,(MatchHistory!$B:$B=$A11)*(MatchHistory!$J:$J<>""),0))} -> 1557
A12: Lou | B12: =COUNTIFS(MatchHistory!$B:$B, $A12, MatchHistory!$C:$C, "Town") -> 52 | C12: =COUNTIFS(MatchHistory!B:B, A12, MatchHistory!C:C, "Town", MatchHistory!D:D, "Win") -> 23 | D12: =IFERROR(__xludf.DUMMYFUNCTION("IF(EQ($B12, 0), TO_PERCENT(0), TO_PERCENT($C12/$B12))"),0.4423076923076923) -> 0.44230769 | E12: =COUNTIFS(MatchHistory!$B:$B, $A12, MatchHistory!$C:$C, "Mafia") -> 10 | F12: =COUNTIFS(MatchHistory!$B:$B, $A12, MatchHistory!$C:$C, "Mafia", MatchHistory!$D:$D, "Win") -> 5 | G12: =IFERROR(__xludf.DUMMYFUNCTION("TO_PERCENT(IFERROR($F12/$E12, 0))"),0.5) -> 0.5 | H12: =SUM(E12, B12) -> 62 | I12: =IFERROR(__xludf.DUMMYFUNCTION("TO_PERCENT(IFERROR(($F12+$C12)/($E12+$B12), 0))"),0.45161290322580644) -> 0.4516129 | J12: {=INDEX(MatchHistory!$G:$G,MATCH(1,(MatchHistory!$B:$B=$A12)*(MatchHistory!$G:$G<>""),0))} -> 31.267898 | K12: {=INDEX(MatchHistory!$H:$H,MATCH(1,(MatchHistory!$B:$B=$A12)*(MatchHistory!$H:$H<>""),0))} -> 5.8569431 | L12: {=INDEX(MatchHistory!$J:$J,MATCH(1,(MatchHistory!$B:$B=$A12)*(MatchHistory!$J:$J<>""),0))} -> 1529
A13: Mintt | B13: =COUNTIFS(MatchHistory!$B:$B, $A13, MatchHistory!$C:$C, "Town") -> 38 | C13: =COUNTIFS(MatchHistory!B:B, A13, MatchHistory!C:C, "Town", MatchHistory!D:D, "Win") -> 20 | D13: =IFERROR(__xludf.DUMMYFUNCTION("IF(EQ($B13, 0), TO_PERCENT(0), TO_PERCENT($C13/$B13))"),0.5263157894736842) -> 0.52631579 | E13: =COUNTIFS(MatchHistory!$B:$B, $A13, MatchHistory!$C:$C, "Mafia") -> 10 | F13: =COUNTIFS(MatchHistory!$B:$B, $A13, MatchHistory!$C:$C, "Mafia", MatchHistory!$D:$D, "Win") -> 5 | G13: =IFERROR(__xludf.DUMMYFUNCTION("TO_PERCENT(IFERROR($F13/$E13, 0))"),0.5) -> 0.5 | H13: =SUM(E13, B13) -> 48 | I13: =IFERROR(__xludf.DUMMYFUNCTION("TO_PERCENT(IFERROR(($F13+$C13)/($E13+$B13), 0))"),0.5208333333333334) -> 0.52083333 | J13: {=INDEX(MatchHistory!$G:$G,MATCH(1,(MatchHistory!$B:$B=$A13)*(MatchHistory!$G:$G<>""),0))} -> 31.34669 | K13: {=INDEX(MatchHistory!$H:$H,MATCH(1,(MatchHistory!$B:$B=$A13)*(MatchHistory!$H:$H<>""),0))} -> 6.0979417 | L13: {=INDEX(MatchHistory!$J:$J,MATCH(1,(MatchHistory!$B:$B=$A13)*(MatchHistory!$J:$J<>""),0))} -> 1510
A14: Chester | B14: =COUNTIFS(MatchHistory!$B:$B, $A14, MatchHistory!$C:$C, "Town") -> 41 | C14: =COUNTIFS(MatchHistory!B:B, A14, MatchHistory!C:C, "Town", MatchHistory!D:D, "Win") -> 16 | D14: =IFERROR(__xludf.DUMMYFUNCTION("IF(EQ($B14, 0), TO_PERCENT(0), TO_PERCENT($C14/$B14))"),0.3902439024390244) -> 0.3902439 | E14: =COUNTIFS(MatchHistory!$B:$B, $A14, MatchHistory!$C:$C, "Mafia") -> 9 | F14: =COUNTIFS(MatchHistory!$B:$B, $A14, MatchHistory!$C:$C, "Mafia", MatchHistory!$D:$D, "Win") -> 6 | G14: =IFERROR(__xludf.DUMMYFUNCTION("TO_PERCENT(IFERROR($F14/$E14, 0))"),0.6666666666666666) -> 0.66666667 | H14: =SUM(E14, B14) -> 50 | I14: =IFERROR(__xludf.DUMMYFUNCTION("TO_PERCENT(IFERROR(($F14+$C14)/($E14+$B14), 0))"),0.44) -> 0.44 | J14: {=INDEX(MatchHistory!$G:$G,MATCH(1,(MatchHistory!$B:$B=$A14)*(MatchHistory!$G:$G<>""),0))} -> 31.269928 | K14: {=INDEX(MatchHistory!$H:$H,MATCH(1,(MatchHistory!$B:$B=$A14)*(MatchHistory!$H:$H<>""),0))} -> 6.1968095 | L14: {=INDEX(MatchHistory!$J:$J,MATCH(1,(MatchHistory!$B:$B=$A14)*(MatchHistory!$J:$J<>""),0))} -> 1494
A15: Carson | B15: =COUNTIFS(MatchHistory!$B:$B, $A15, MatchHistory!$C:$C, "Town") -> 52 | C15: =COUNTIFS(MatchHistory!B:B, A15, MatchHistory!C:C, "Town", MatchHistory!D:D, "Win") -> 24 | D15: =IFERROR(__xludf.DUMMYFUNCTION("IF(EQ($B15, 0), TO_PERCENT(0), TO_PERCENT($C15/$B15))"),0.46153846153846156) -> 0.46153846 | E15: =COUNTIFS(MatchHistory!$B:$B, $A15, MatchHistory!$C:$C, "Mafia") -> 9 | F15: =COUNTIFS(MatchHistory!$B:$B, $A15, MatchHistory!$C:$C, "Mafia", MatchHistory!$D:$D, "Win") -> 3 | G15: =IFERROR(__xludf.DUMMYFUNCTION("TO_PERCENT(IFERROR($F15/$E15, 0))"),0.3333333333333333) -> 0.33333333 | H15: =SUM(E15, B15) -> 61 | I15: =IFERROR(__xludf.DUMMYFUNCTION("TO_PERCENT(IFERROR(($F15+$C15)/($E15+$B15), 0))"),0.4426229508196721) -> 0.44262295 | J15: {=INDEX(MatchHistory!$G:$G,MATCH(1,(MatchHistory!$B:$B=$A15)*(MatchHistory!$G:$G<>""),0))} -> 30.325724 | K15: {=INDEX(MatchHistory!$H:$H,MATCH(1,(MatchHistory!$B:$B=$A15)*(MatchHistory!$H:$H<>""),0))} -> 5.7922464 | L15: {=INDEX(MatchHistory!$J:$J,MATCH(1,(MatchHistory!$B:$B=$A15)*(MatchHistory!$J:$J<>""),0))} -> 1471
A16: Matt | B16: =COUNTIFS(MatchHistory!$B:$B, $A16, MatchHistory!$C:$C, "Town") -> 11 | C16: =COUNTIFS(MatchHistory!B:B, A16, MatchHistory!C:C, "Town", MatchHistory!D:D, "Win") -> 5 | D16: =IFERROR(__xludf.DUMMYFUNCTION("IF(EQ($B16, 0), TO_PERCENT(0), TO_PERCENT($C16/$B16))"),0.45454545454545453) -> 0.45454545 | E16: =COUNTIFS(MatchHistory!$B:$B, $A16, MatchHistory!$C:$C, "Mafia") -> 0 | F16: =COUNTIFS(MatchHistory!$B:$B, $A16, MatchHistory!$C:$C, "Mafia", MatchHistory!$D:$D, "Win") -> 0 | G16: =IFERROR(__xludf.DUMMYFUNCTION("TO_PERCENT(IFERROR($F16/$E16, 0))"),0.0) -> 0 | H16: =SUM(E16, B16) -> 11 | I16: =IFERROR(__xludf.DUMMYFUNCTION("TO_PERCENT(IFERROR(($F16+$C16)/($E16+$B16), 0))"),0.45454545454545453) -> 0.45454545 | J16: {=INDEX(MatchHistory!$G:$G,MATCH(1,(MatchHistory!$B:$B=$A16)*(MatchHistory!$G:$G<>""),0))} -> 32.960848 | K16: {=INDEX(MatchHistory!$H:$H,MATCH(1,(MatchHistory!$B:$B=$A16)*(MatchHistory!$H:$H<>""),0))} -> 7.6433982 | L16: {=INDEX(MatchHistory!$J:$J,MATCH(1,(MatchHistory!$B:$B=$A16)*(MatchHistory!$J:$J<>""),0))} -> 1462
A17: Streety | B17: =COUNTIFS(MatchHistory!$B:$B, $A17, MatchHistory!$C:$C, "Town") -> 28 | C17: =COUNTIFS(MatchHistory!B:B, A17, MatchHistory!C:C, "Town", MatchHistory!D:D, "Win") -> 13 | D17: =IFERROR(__xludf.DUMMYFUNCTION("IF(EQ($B17, 0), TO_PERCENT(0), TO_PERCENT($C17/$B17))"),0.4642857142857143) -> 0.46428571 | E17: =COUNTIFS(MatchHistory!$B:$B, $A17, MatchHistory!$C:$C, "Mafia") -> 8 | F17: =COUNTIFS(MatchHistory!$B:$B, $A17, MatchHistory!$C:$C, "Mafia", MatchHistory!$D:$D, "Win") -> 5 | G17: =IFERROR(__xludf.DUMMYFUNCTION("TO_PERCENT(IFERROR($F17/$E17, 0))"),0.625) -> 0.625 | H17: =SUM(E17, B17) -> 36 | I17: =IFERROR(__xludf.DUMMYFUNCTION("TO_PERCENT(IFERROR(($F17+$C17)/($E17+$B17), 0))"),0.5) -> 0.5 | J17: {=INDEX(MatchHistory!$G:$G,MATCH(1,(MatchHistory!$B:$B=$A17)*(MatchHistory!$G:$G<>""),0))} -> 31.0274 | K17: {=INDEX(MatchHistory!$H:$H,MATCH(1,(MatchHistory!$B:$B=$A17)*(MatchHistory!$H:$H<>""),0))} -> 6.5269233 | L17: {=INDEX(MatchHistory!$J:$J,MATCH(1,(MatchHistory!$B:$B=$A17)*(MatchHistory!$J:$J<>""),0))} -> 1444
A18: Whyin | B18: =COUNTIFS(MatchHistory!$B:$B, $A18, MatchHistory!$C:$C, "Town") -> 34 | C18: =COUNTIFS(MatchHistory!B:B, A18, MatchHistory!C:C, "Town", MatchHistory!D:D, "Win") -> 15 | D18: =IFERROR(__xludf.DUMMYFUNCTION("IF(EQ($B18, 0), TO_PERCENT(0), TO_PERCENT($C18/$B18))"),0.4411764705882353) -> 0.44117647 | E18: =COUNTIFS(MatchHistory!$B:$B, $A18, MatchHistory!$C:$C, "Mafia") -> 10 | F18: =COUNTIFS(MatchHistory!$B:$B, $A18, MatchHistory!$C:$C, "Mafia", MatchHistory!$D:$D, "Win") -> 5 | G18: =IFERROR(__xludf.DUMMYFUNCTION("TO_PERCENT(IFERROR($F18/$E18, 0))"),0.5) -> 0.5 | H18: =SUM(E18, B18) -> 44 | I18: =IFERROR(__xludf.DUMMYFUNCTION("TO_PERCENT(IFERROR(($F18+$C18)/($E18+$B18), 0))"),0.45454545454545453) -> 0.45454545 | J18: {=INDEX(MatchHistory!$G:$G,MATCH(1,(MatchHistory!$B:$B=$A18)*(MatchHistory!$G:$G<>""),0))} -> 30.431018 | K18: {=INDEX(MatchHistory!$H:$H,MATCH(1,(MatchHistory!$B:$B=$A18)*(MatchHistory!$H:$H<>""),0))} -> 6.3408373 | L18: {=INDEX(MatchHistory!$J:$J,MATCH(1,(MatchHistory!$B:$B=$A18)*(MatchHistory!$J:$J<>""),0))} -> 1423
A19: Chelsea | B19: =COUNTIFS(MatchHistory!$B:$B, $A19, MatchHistory!$C:$C, "Town") -> 38 | C19: =COUNTIFS(MatchHistory!B:B, A19, MatchHistory!C:C, "Town", MatchHistory!D:D, "Win") -> 15 | D19: =IFERROR(__xludf.DUMMYFUNCTION("IF(EQ($B19, 0), TO_PERCENT(0), TO_PERCENT($C19/$B19))"),0.39473684210526316) -> 0.39473684 | E19: =COUNTIFS(MatchHistory!$B:$B, $A19, MatchHistory!$C:$C, "Mafia") -> 6 | F19: =COUNTIFS(MatchHistory!$B:$B, $A19, MatchHistory!$C:$C, "Mafia", MatchHistory!$D:$D, "Win") -> 2 | G19: =IFERROR(__xludf.DUMMYFUNCTION("TO_PERCENT(IFERROR($F19/$E19, 0))"),0.3333333333333333) -> 0.33333333 | H19: =SUM(E19, B19) -> 44 | I19: =IFERROR(__xludf.DUMMYFUNCTION("TO_PERCENT(IFERROR(($F19+$C19)/($E19+$B19), 0))"),0.38636363636363635) -> 0.38636364 | J19: {=INDEX(MatchHistory!$G:$G,MATCH(1,(MatchHistory!$B:$B=$A19)*(MatchHistory!$G:$G<>""),0))} -> 30.385304 | K19: {=INDEX(MatchHistory!$H:$H,MATCH(1,(MatchHistory!$B:$B=$A19)*(MatchHistory!$H:$H<>""),0))} -> 6.3232698 | L19: {=INDEX(MatchHistory!$J:$J,MATCH(1,(MatchHistory!$B:$B=$A19)*(MatchHistory!$J:$J<>""),0))} -> 1421
A20: Gilbert | B20: =COUNTIFS(MatchHistory!$B:$B, $A20, MatchHistory!$C:$C, "Town") -> 30 | C20: =COUNTIFS(MatchHistory!B:B, A20, MatchHistory!C:C, "Town", MatchHistory!D:D, "Win") -> 15 | D20: =IFERROR(__xludf.DUMMYFUNCTION("IF(EQ($B20, 0), TO_PERCENT(0), TO_PERCENT($C20/$B20))"),0.5) -> 0.5 | E20: =COUNTIFS(MatchHistory!$B:$B, $A20, MatchHistory!$C:$C, "Mafia") -> 8 | F20: =COUNTIFS(MatchHistory!$B:$B, $A20, MatchHistory!$C:$C, "Mafia", MatchHistory!$D:$D, "Win") -> 3 | G20: =IFERROR(__xludf.DUMMYFUNCTION("TO_PERCENT(IFERROR($F20/$E20, 0))"),0.375) -> 0.375 | H20: =SUM(E20, B20) -> 38 | I20: =IFERROR(__xludf.DUMMYFUNCTION("TO_PERCENT(IFERROR(($F20+$C20)/($E20+$B20), 0))"),0.47368421052631576) -> 0.47368421 | J20: {=INDEX(MatchHistory!$G:$G,MATCH(1,(MatchHistory!$B:$B=$A20)*(MatchHistory!$G:$G<>""),0))} -> 30.32656 | K20: {=INDEX(MatchHistory!$H:$H,MATCH(1,(MatchHistory!$B:$B=$A20)*(MatchHistory!$H:$H<>""),0))} -> 6.471524 | L20: {=INDEX(MatchHistory!$J:$J,MATCH(1,(MatchHistory!$B:$B=$A20)*(MatchHistory!$J:$J<>""),0))} -> 1402
A21: Rick | B21: =COUNTIFS(MatchHistory!$B:$B, $A21, MatchHistory!$C:$C, "Town") -> 20 | C21: =COUNTIFS(MatchHistory!B:B, A21, MatchHistory!C:C, "Town", MatchHistory!D:D, "Win") -> 7 | D21: =IFERROR(__xludf.DUMMYFUNCTION("IF(EQ($B21, 0), TO_PERCENT(0), TO_PERCENT($C21/$B21))"),0.35) -> 0.35 | E21: =COUNTIFS(MatchHistory!$B:$B, $A21, MatchHistory!$C:$C, "Mafia") -> 6 | F21: =COUNTIFS(MatchHistory!$B:$B, $A21, MatchHistory!$C:$C, "Mafia", MatchHistory!$D:$D, "Win") -> 6 | G21: =IFERROR(__xludf.DUMMYFUNCTION("TO_PERCENT(IFERROR($F21/$E21, 0))"),1.0) -> 1 | H21: =SUM(E21, B21) -> 26 | I21: =IFERROR(__xludf.DUMMYFUNCTION("TO_PERCENT(IFERROR(($F21+$C21)/($E21+$B21), 0))"),0.5) -> 0.5 | J21: {=INDEX(MatchHistory!$G:$G,MATCH(1,(MatchHistory!$B:$B=$A21)*(MatchHistory!$G:$G<>""),0))} -> 30.354063 | K21: {=INDEX(MatchHistory!$H:$H,MATCH(1,(MatchHistory!$B:$B=$A21)*(MatchHistory!$H:$H<>""),0))} -> 6.9244329 | L21: {=INDEX(MatchHistory!$J:$J,MATCH(1,(MatchHistory!$B:$B=$A21)*(MatchHistory!$J:$J<>""),0))} -> 1358
A22: Cj | B22: =COUNTIFS(MatchHistory!$B:$B, $A22, MatchHistory!$C:$C, "Town") -> 14 | C22: =COUNTIFS(MatchHistory!B:B, A22, MatchHistory!C:C, "Town", MatchHistory!D:D, "Win") -> 7 | D22: =IFERROR(__xludf.DUMMYFUNCTION("IF(EQ($B22, 0), TO_PERCENT(0), TO_PERCENT($C22/$B22))"),0.5) -> 0.5 | E22: =COUNTIFS(MatchHistory!$B:$B, $A22, MatchHistory!$C:$C, "Mafia") -> 3 | F22: =COUNTIFS(MatchHistory!$B:$B, $A22, MatchHistory!$C:$C, "Mafia", MatchHistory!$D:$D, "Win") -> 1 | G22: =IFERROR(__xludf.DUMMYFUNCTION("TO_PERCENT(IFERROR($F22/$E22, 0))"),0.3333333333333333) -> 0.33333333 | H22: =SUM(E22, B22) -> 17 | I22: =IFERROR(__xludf.DUMMYFUNCTION("TO_PERCENT(IFERROR(($F22+$C22)/($E22+$B22), 0))"),0.47058823529411764) -> 0.47058824 | J22: {=INDEX(MatchHistory!$G:$G,MATCH(1,(MatchHistory!$B:$B=$A22)*(MatchHistory!$G:$G<>""),0))} -> 30.34947 | K22: {=INDEX(MatchHistory!$H:$H,MATCH(1,(MatchHistory!$B:$B=$A22)*(MatchHistory!$H:$H<>""),0))} -> 7.2862664 | L22: {=INDEX(MatchHistory!$J:$J,MATCH(1,(MatchHistory!$B:$B=$A22)*(MatchHistory!$J:$J<>""),0))} -> 1321
A23: Siggy | B23: =COUNTIFS(MatchHistory!$B:$B, $A23, MatchHistory!$C:$C, "Town") -> 8 | C23: =COUNTIFS(MatchHistory!B:B, A23, MatchHistory!C:C, "Town", MatchHistory!D:D, "Win") -> 6 | D23: =IFERROR(__xludf.DUMMYFUNCTION("IF(EQ($B23, 0), TO_PERCENT(0), TO_PERCENT($C23/$B23))"),0.75) -> 0.75 | E23: =COUNTIFS(MatchHistory!$B:$B, $A23, MatchHistory!$C:$C, "Mafia") -> 2 | F23: =COUNTIFS(MatchHistory!$B:$B, $A23, MatchHistory!$C:$C, "Mafia", MatchHistory!$D:$D, "Win") -> 1 | G23: =IFERROR(__xludf.DUMMYFUNCTION("TO_PERCENT(IFERROR($F23/$E23, 0))"),0.5) -> 0.5 | H23: =SUM(E23, B23) -> 10 | I23: =IFERROR(__xludf.DUMMYFUNCTION("TO_PERCENT(IFERROR(($F23+$C23)/($E23+$B23), 0))"),0.7) -> 0.7 | J23: {=INDEX(MatchHistory!$G:$G,MATCH(1,(MatchHistory!$B:$B=$A23)*(MatchHistory!$G:$G<>""),0))} -> 30.685932 | K23: {=INDEX(MatchHistory!$H:$H,MATCH(1,(MatchHistory!$B:$B=$A23)*(MatchHistory!$H:$H<>""),0))} -> 7.5954336 | L23: {=INDEX(MatchHistory!$J:$J,MATCH(1,(MatchHistory!$B:$B=$A23)*(MatchHistory!$J:$J<>""),0))} -> 1312
A24: Badpants | B24: =COUNTIFS(MatchHistory!$B:$B, $A24, MatchHistory!$C:$C, "Town") -> 61 | C24: =COUNTIFS(MatchHistory!B:B, A24, MatchHistory!C:C, "Town", MatchHistory!D:D, "Win") -> 22 | D24: =IFERROR(__xludf.DUMMYFUNCTION("IF(EQ($B24, 0), TO_PERCENT(0), TO_PERCENT($C24/$B24))"),0.36065573770491804) -> 0.36065574 | E24: =COUNTIFS(MatchHistory!$B:$B, $A24, MatchHistory!$C:$C, "Mafia") -> 18 | F24: =COUNTIFS(MatchHistory!$B:$B, $A24, MatchHistory!$C:$C, "Mafia", MatchHistory!$D:$D, "Win") -> 9 | G24: =IFERROR(__xludf.DUMMYFUNCTION("TO_PERCENT(IFERROR($F24/$E24, 0))"),0.5) -> 0.5 | H24: =SUM(E24, B24) -> 79 | I24: =IFERROR(__xludf.DUMMYFUNCTION("TO_PERCENT(IFERROR(($F24+$C24)/($E24+$B24), 0))"),0.3924050632911392) -> 0.39240506 | J24: {=INDEX(MatchHistory!$G:$G,MATCH(1,(MatchHistory!$B:$B=$A24)*(MatchHistory!$G:$G<>""),0))} -> 27.412338 | K24: {=INDEX(MatchHistory!$H:$H,MATCH(1,(MatchHistory!$B:$B=$A24)*(MatchHistory!$H:$H<>""),0))} -> 5.4212107 | L24: {=INDEX(MatchHistory!$J:$J,MATCH(1,(MatchHistory!$B:$B=$A24)*(MatchHistory!$J:$J<>""),0))} -> 1311
A25: Keegan | B25: =COUNTIFS(MatchHistory!$B:$B, $A25, MatchHistory!$C:$C, "Town") -> 16 | C25: =COUNTIFS(MatchHistory!B:B, A25, MatchHistory!C:C, "Town", MatchHistory!D:D, "Win") -> 7 | D25: =IFERROR(__xludf.DUMMYFUNCTION("IF(EQ($B25, 0), TO_PERCENT(0), TO_PERCENT($C25/$B25))"),0.4375) -> 0.4375 | E25: =COUNTIFS(MatchHistory!$B:$B, $A25, MatchHistory!$C:$C, "Mafia") -> 4 | F25: =COUNTIFS(MatchHistory!$B:$B, $A25, MatchHistory!$C:$C, "Mafia", MatchHistory!$D:$D, "Win") -> 3 | G25: =IFERROR(__xludf.DUMMYFUNCTION("TO_PERCENT(IFERROR($F25/$E25, 0))"),0.75) -> 0.75 | H25: =SUM(E25, B25) -> 20 | I25: =IFERROR(__xludf.DUMMYFUNCTION("TO_PERCENT(IFERROR(($F25+$C25)/($E25+$B25), 0))"),0.5) -> 0.5 | J25: {=INDEX(MatchHistory!$G:$G,MATCH(1,(MatchHistory!$B:$B=$A25)*(MatchHistory!$G:$G<>""),0))} -> 30.105009 | K25: {=INDEX(MatchHistory!$H:$H,MATCH(1,(MatchHistory!$B:$B=$A25)*(MatchHistory!$H:$H<>""),0))} -> 7.2456647 | L25: {=INDEX(MatchHistory!$J:$J,MATCH(1,(MatchHistory!$B:$B=$A25)*(MatchHistory!$J:$J<>""),0))} -> 1308
A26: Xcync | B26: =COUNTIFS(MatchHistory!$B:$B, $A26, MatchHistory!$C:$C, "Town") -> 14 | C26: =COUNTIFS(MatchHistory!B:B, A26, MatchHistory!C:C, "Town", MatchHistory!D:D, "Win") -> 7 | D26: =IFERROR(__xludf.DUMMYFUNCTION("IF(EQ($B26, 0), TO_PERCENT(0), TO_PERCENT($C26/$B26))"),0.5) -> 0.5 | E26: =COUNTIFS(MatchHistory!$B:$B, $A26, MatchHistory!$C:$C, "Mafia") -> 5 | F26: =COUNTIFS(MatchHistory!$B:$B, $A26, MatchHistory!$C:$C, "Mafia", MatchHistory!$D:$D, "Win") -> 3 | G26: =IFERROR(__xludf.DUMMYFUNCTION("TO_PERCENT(IFERROR($F26/$E26, 0))"),0.6) -> 0.6 | H26: =SUM(E26, B26) -> 19 | I26: =IFERROR(__xludf.DUMMYFUNCTION("TO_PERCENT(IFERROR(($F26+$C26)/($E26+$B26), 0))"),0.5263157894736842) -> 0.52631579 | J26: {=INDEX(MatchHistory!$G:$G,MATCH(1,(MatchHistory!$B:$B=$A26)*(MatchHistory!$G:$G<>""),0))} -> 30.180624 | K26: {=INDEX(MatchHistory!$H:$H,MATCH(1,(MatchHistory!$B:$B=$A26)*(MatchHistory!$H:$H<>""),0))} -> 7.3048589 | L26: {=INDEX(MatchHistory!$J:$J,MATCH(1,(MatchHistory!$B:$B=$A26)*(MatchHistory!$J:$J<>""),0))} -> 1307
A27: Kden | B27: =COUNTIFS(MatchHistory!$B:$B, $A27, MatchHistory!$C:$C, "Town") -> 44 | C27: =COUNTIFS(MatchHistory!B:B, A27, MatchHistory!C:C, "Town", MatchHistory!D:D, "Win") -> 14 | D27: =IFERROR(__xludf.DUMMYFUNCTION("IF(EQ($B27, 0), TO_PERCENT(0), TO_PERCENT($C27/$B27))"),0.3181818181818182) -> 0.31818182 | E27: =COUNTIFS(MatchHistory!$B:$B, $A27, MatchHistory!$C:$C, "Mafia") -> 9 | F27: =COUNTIFS(MatchHistory!$B:$B, $A27, MatchHistory!$C:$C, "Mafia", MatchHistory!$D:$D, "Win") -> 5 | G27: =IFERROR(__xludf.DUMMYFUNCTION("TO_PERCENT(IFERROR($F27/$E27, 0))"),0.5555555555555556) -> 0.55555556 | H27: =SUM(E27, B27) -> 53 | I27: =IFERROR(__xludf.DUMMYFUNCTION("TO_PERCENT(IFERROR(($F27+$C27)/($E27+$B27), 0))"),0.3584905660377358) -> 0.35849057 | J27: {=INDEX(MatchHistory!$G:$G,MATCH(1,(MatchHistory!$B:$B=$A27)*(MatchHistory!$G:$G<>""),0))} -> 28.313355 | K27: {=INDEX(MatchHistory!$H:$H,MATCH(1,(MatchHistory!$B:$B=$A27)*(MatchHistory!$H:$H<>""),0))} -> 6.0672109 | L27: {=INDEX(MatchHistory!$J:$J,MATCH(1,(MatchHistory!$B:$B=$A27)*(MatchHistory!$J:$J<>""),0))} -> 1306
A28: Strik3r | B28: =COUNTIFS(MatchHistory!$B:$B, $A28, MatchHistory!$C:$C, "Town") -> 22 | C28: =COUNTIFS(MatchHistory!B:B, A28, MatchHistory!C:C, "Town", MatchHistory!D:D, "Win") -> 8 | D28: =IFERROR(__xludf.DUMMYFUNCTION("IF(EQ($B28, 0), TO_PERCENT(0), TO_PERCENT($C28/$B28))"),0.36363636363636365) -> 0.36363636 | E28: =COUNTIFS(MatchHistory!$B:$B, $A28, MatchHistory!$C:$C, "Mafia") -> 11 | F28: =COUNTIFS(MatchHistory!$B:$B, $A28, MatchHistory!$C:$C, "Mafia", MatchHistory!$D:$D, "Win") -> 7 | G28: =IFERROR(__xludf.DUMMYFUNCTION("TO_PERCENT(IFERROR($F28/$E28, 0))"),0.6363636363636364) -> 0.63636364 | H28: =SUM(E28, B28) -> 33 | I28: =IFERROR(__xludf.DUMMYFUNCTION("TO_PERCENT(IFERROR(($F28+$C28)/($E28+$B28), 0))"),0.45454545454545453) -> 0.45454545 | J28: {=INDEX(MatchHistory!$G:$G,MATCH(1,(MatchHistory!$B:$B=$A28)*(MatchHistory!$G:$G<>""),0))} -> 28.631602 | K28: {=INDEX(MatchHistory!$H:$H,MATCH(1,(MatchHistory!$B:$B=$A28)*(MatchHistory!$H:$H<>""),0))} -> 6.5821928 | L28: {=INDEX(MatchHistory!$J:$J,MATCH(1,(MatchHistory!$B:$B=$A28)*(MatchHistory!$J:$J<>""),0))} -> 1276
A29: Josh | B29: =COUNTIFS(MatchHistory!$B:$B, $A29, MatchHistory!$C:$C, "Town") -> 12 | C29: =COUNTIFS(MatchHistory!B:B, A29, MatchHistory!C:C, "Town", MatchHistory!D:D, "Win") -> 8 | D29: =IFERROR(__xludf.DUMMYFUNCTION("IF(EQ($B29, 0), TO_PERCENT(0), TO_PERCENT($C29/$B29))"),0.6666666666666666) -> 0.66666667 | E29: =COUNTIFS(MatchHistory!$B:$B, $A29, MatchHistory!$C:$C, "Mafia") -> 6 | F29: =COUNTIFS(MatchHistory!$B:$B, $A29, MatchHistory!$C:$C, "Mafia", MatchHistory!$D:$D, "Win") -> 3 | G29: =IFERROR(__xludf.DUMMYFUNCTION("TO_PERCENT(IFERROR($F29/$E29, 0))"),0.5) -> 0.5 | H29: =SUM(E29, B29) -> 18 | I29: =IFERROR(__xludf.DUMMYFUNCTION("TO_PERCENT(IFERROR(($F29+$C29)/($E29+$B29), 0))"),0.6111111111111112) -> 0.61111111 | J29: {=INDEX(MatchHistory!$G:$G,MATCH(1,(MatchHistory!$B:$B=$A29)*(MatchHistory!$G:$G<>""),0))} -> 28.979614 | K29: {=INDEX(MatchHistory!$H:$H,MATCH(1,(MatchHistory!$B:$B=$A29)*(MatchHistory!$H:$H<>""),0))} -> 7.2783272 | L29: {=INDEX(MatchHistory!$J:$J,MATCH(1,(MatchHistory!$B:$B=$A29)*(MatchHistory!$J:$J<>""),0))} -> 1228
A30: Motr | B30: =COUNTIFS(MatchHistory!$B:$B, $A30, MatchHistory!$C:$C, "Town") -> 20 | C30: =COUNTIFS(MatchHistory!B:B, A30, MatchHistory!C:C, "Town", MatchHistory!D:D, "Win") -> 10 | D30: =IFERROR(__xludf.DUMMYFUNCTION("IF(EQ($B30, 0), TO_PERCENT(0), TO_PERCENT($C30/$B30))"),0.5) -> 0.5 | E30: =COUNTIFS(MatchHistory!$B:$B, $A30, MatchHistory!$C:$C, "Mafia") -> 11 | F30: =COUNTIFS(MatchHistory!$B:$B, $A30, MatchHistory!$C:$C, "Mafia", MatchHistory!$D:$D, "Win") -> 5 | G30: =IFERROR(__xludf.DUMMYFUNCTION("TO_PERCENT(IFERROR($F30/$E30, 0))"),0.45454545454545453) -> 0.45454545 | H30: =SUM(E30, B30) -> 31 | I30: =IFERROR(__xludf.DUMMYFUNCTION("TO_PERCENT(IFERROR(($F30+$C30)/($E30+$B30), 0))"),0.4838709677419355) -> 0.48387097 | J30: {=INDEX(MatchHistory!$G:$G,MATCH(1,(MatchHistory!$B:$B=$A30)*(MatchHistory!$G:$G<>""),0))} -> 27.910313 | K30: {=INDEX(MatchHistory!$H:$H,MATCH(1,(MatchHistory!$B:$B=$A30)*(MatchHistory!$H:$H<>""),0))} -> 6.6196349 | L30: {=INDEX(MatchHistory!$J:$J,MATCH(1,(MatchHistory!$B:$B=$A30)*(MatchHistory!$J:$J<>""),0))} -> 1223
A31: Vincent | B31: =COUNTIFS(MatchHistory!$B:$B, $A31, MatchHistory!$C:$C, "Town") -> 4 | C31: =COUNTIFS(MatchHistory!B:B, A31, MatchHistory!C:C, "Town", MatchHistory!D:D, "Win") -> 3 | D31: =IFERROR(__xludf.DUMMYFUNCTION("IF(EQ($B31, 0), TO_PERCENT(0), TO_PERCENT($C31/$B31))"),0.75) -> 0.75 | E31: =COUNTIFS(MatchHistory!$B:$B, $A31, MatchHistory!$C:$C, "Mafia") -> 0 | F31: =COUNTIFS(MatchHistory!$B:$B, $A31, MatchHistory!$C:$C, "Mafia", MatchHistory!$D:$D, "Win") -> 0 | G31: =IFERROR(__xludf.DUMMYFUNCTION("TO_PERCENT(IFERROR($F31/$E31, 0))"),0.0) -> 0 | H31: =SUM(E31, B31) -> 4 | I31: =IFERROR(__xludf.DUMMYFUNCTION("TO_PERCENT(IFERROR(($F31+$C31)/($E31+$B31), 0))"),0.75) -> 0.75 | J31: {=INDEX(MatchHistory!$G:$G,MATCH(1,(MatchHistory!$B:$B=$A31)*(MatchHistory!$G:$G<>""),0))} -> 29.963729 | K31: {=INDEX(MatchHistory!$H:$H,MATCH(1,(MatchHistory!$B:$B=$A31)*(MatchHistory!$H:$H<>""),0))} -> 8.0292572 | L31: {=INDEX(MatchHistory!$J:$J,MATCH(1,(MatchHistory!$B:$B=$A31)*(MatchHistory!$J:$J<>""),0))} -> 1219
A32: Svaan | B32: =COUNTIFS(MatchHistory!$B:$B, $A32, MatchHistory!$C:$C, "Town") -> 24 | C32: =COUNTIFS(MatchHistory!B:B, A32, MatchHistory!C:C, "Town", MatchHistory!D:D, "Win") -> 9 | D32: =IFERROR(__xludf.DUMMYFUNCTION("IF(EQ($B32, 0), TO_PERCENT(0), TO_PERCENT($C32/$B32))"),0.375) -> 0.375 | E32: =COUNTIFS(MatchHistory!$B:$B, $A32, MatchHistory!$C:$C, "Mafia") -> 8 | F32: =COUNTIFS(MatchHistory!$B:$B, $A32, MatchHistory!$C:$C, "Mafia", MatchHistory!$D:$D, "Win") -> 4 | G32: =IFERROR(__xludf.DUMMYFUNCTION("TO_PERCENT(IFERROR($F32/$E32, 0))"),0.5) -> 0.5 | H32: =SUM(E32, B32) -> 32 | I32: =IFERROR(__xludf.DUMMYFUNCTION("TO_PERCENT(IFERROR(($F32+$C32)/($E32+$B32), 0))"),0.40625) -> 0.40625 | J32: {=INDEX(MatchHistory!$G:$G,MATCH(1,(MatchHistory!$B:$B=$A32)*(MatchHistory!$G:$G<>""),0))} -> 27.920206 | K32: {=INDEX(MatchHistory!$H:$H,MATCH(1,(MatchHistory!$B:$B=$A32)*(MatchHistory!$H:$H<>""),0))} -> 6.7017035 | L32: {=INDEX(MatchHistory!$J:$J,MATCH(1,(MatchHistory!$B:$B=$A32)*(MatchHistory!$J:$J<>""),0))} -> 1215
A33: Plen | B33: =COUNTIFS(MatchHistory!$B:$B, $A33, MatchHistory!$C:$C, "Town") -> 62 | C33: =COUNTIFS(MatchHistory!B:B, A33, MatchHistory!C:C, "Town", MatchHistory!D:D, "Win") -> 23 | D33: =IFERROR(__xludf.DUMMYFUNCTION("IF(EQ($B33, 0), TO_PERCENT(0), TO_PERCENT($C33/$B33))"),0.3709677419354839) -> 0.37096774 | E33: =COUNTIFS(MatchHistory!$B:$B, $A33, MatchHistory!$C:$C, "Mafia") -> 11 | F33: =COUNTIFS(MatchHistory!$B:$B, $A33, MatchHistory!$C:$C, "Mafia", MatchHistory!$D:$D, "Win") -> 4 | G33: =IFERROR(__xludf.DUMMYFUNCTION("TO_PERCENT(IFERROR($F33/$E33, 0))"),0.36363636363636365) -> 0.36363636 | H33: =SUM(E33, B33) -> 73 | I33: =IFERROR(__xludf.DUMMYFUNCTION("TO_PERCENT(IFERROR(($F33+$C33)/($E33+$B33), 0))"),0.3698630136986301) -> 0.36986301 | J33: {=INDEX(MatchHistory!$G:$G,MATCH(1,(MatchHistory!$B:$B=$A33)*(MatchHistory!$G:$G<>""),0))} -> 25.765842 | K33: {=INDEX(MatchHistory!$H:$H,MATCH(1,(MatchHistory!$B:$B=$A33)*(MatchHistory!$H:$H<>""),0))} -> 5.5795004 | L33: {=INDEX(MatchHistory!$J:$J,MATCH(1,(MatchHistory!$B:$B=$A33)*(MatchHistory!$J:$J<>""),0))} -> 1183
A34: Crispy | B34: =COUNTIFS(MatchHistory!$B:$B, $A34, MatchHistory!$C:$C, "Town") -> 3 | C34: =COUNTIFS(MatchHistory!B:B, A34, MatchHistory!C:C, "Town", MatchHistory!D:D, "Win") -> 2 | D34: =IFERROR(__xludf.DUMMYFUNCTION("IF(EQ($B34, 0), TO_PERCENT(0), TO_PERCENT($C34/$B34))"),0.6666666666666666) -> 0.66666667 | E34: =COUNTIFS(MatchHistory!$B:$B, $A34, MatchHistory!$C:$C, "Mafia") -> 1 | F34: =COUNTIFS(MatchHistory!$B:$B, $A34, MatchHistory!$C:$C, "Mafia", MatchHistory!$D:$D, "Win") -> 1 | G34: =IFERROR(__xludf.DUMMYFUNCTION("TO_PERCENT(IFERROR($F34/$E34, 0))"),1.0) -> 1 | H34: =SUM(E34, B34) -> 4 | I34: =IFERROR(__xludf.DUMMYFUNCTION("TO_PERCENT(IFERROR(($F34+$C34)/($E34+$B34), 0))"),0.75) -> 0.75 | J34: {=INDEX(MatchHistory!$G:$G,MATCH(1,(MatchHistory!$B:$B=$A34)*(MatchHistory!$G:$G<>""),0))} -> 29.135973 | K34: {=INDEX(MatchHistory!$H:$H,MATCH(1,(MatchHistory!$B:$B=$A34)*(MatchHistory!$H:$H<>""),0))} -> 8.0048127 | L34: {=INDEX(MatchHistory!$J:$J,MATCH(1,(MatchHistory!$B:$B=$A34)*(MatchHistory!$J:$J<>""),0))} -> 1165
A35: Cody | B35: =COUNTIFS(MatchHistory!$B:$B, $A35, MatchHistory!$C:$C, "Town") -> 3 | C35: =COUNTIFS(MatchHistory!B:B, A35, MatchHistory!C:C, "Town", MatchHistory!D:D, "Win") -> 3 | D35: =IFERROR(__xludf.DUMMYFUNCTION("IF(EQ($B35, 0), TO_PERCENT(0), TO_PERCENT($C35/$B35))"),1.0) -> 1 | E35: =COUNTIFS(MatchHistory!$B:$B, $A35, MatchHistory!$C:$C, "Mafia") -> 0 | F35: =COUNTIFS(MatchHistory!$B:$B, $A35, MatchHistory!$C:$C, "Mafia", MatchHistory!$D:$D, "Win") -> 0 | G35: =IFERROR(__xludf.DUMMYFUNCTION("TO_PERCENT(IFERROR($F35/$E35, 0))"),0.0) -> 0 | H35: =SUM(E35, B35) -> 3 | I35: =IFERROR(__xludf.DUMMYFUNCTION("TO_PERCENT(IFERROR(($F35+$C35)/($E35+$B35), 0))"),1.0) -> 1 | J35: {=INDEX(MatchHistory!$G:$G,MATCH(1,(MatchHistory!$B:$B=$A35)*(MatchHistory!$G:$G<>""),0))} -> 29.249108 | K35: {=INDEX(MatchHistory!$H:$H,MATCH(1,(MatchHistory!$B:$B=$A35)*(MatchHistory!$H:$H<>""),0))} -> 8.1282995 | L35: {=INDEX(MatchHistory!$J:$J,MATCH(1,(MatchHistory!$B:$B=$A35)*(MatchHistory!$J:$J<>""),0))} -> 1160
A36: Ken | B36: =COUNTIFS(MatchHistory!$B:$B, $A36, MatchHistory!$C:$C, "Town") -> 31 | C36: =COUNTIFS(MatchHistory!B:B, A36, MatchHistory!C:C, "Town", MatchHistory!D:D, "Win") -> 11 | D36: =IFERROR(__xludf.DUMMYFUNCTION("IF(EQ($B36, 0), TO_PERCENT(0), TO_PERCENT($C36/$B36))"),0.3548387096774194) -> 0.35483871 | E36: =COUNTIFS(MatchHistory!$B:$B, $A36, MatchHistory!$C:$C, "Mafia") -> 7 | F36: =COUNTIFS(MatchHistory!$B:$B, $A36, MatchHistory!$C:$C, "Mafia", MatchHistory!$D:$D, "Win") -> 2 | G36: =IFERROR(__xludf.DUMMYFUNCTION("TO_PERCENT(IFERROR($F36/$E36, 0))"),0.2857142857142857) -> 0.28571429 | H36: =SUM(E36, B36) -> 38 | I36: =IFERROR(__xludf.DUMMYFUNCTION("TO_PERCENT(IFERROR(($F36+$C36)/($E36+$B36), 0))"),0.34210526315789475) -> 0.34210526 | J36: {=INDEX(MatchHistory!$G:$G,MATCH(1,(MatchHistory!$B:$B=$A36)*(MatchHistory!$G:$G<>""),0))} -> 26.680961 | K36: {=INDEX(MatchHistory!$H:$H,MATCH(1,(MatchHistory!$B:$B=$A36)*(MatchHistory!$H:$H<>""),0))} -> 6.4845692 | L36: {=INDEX(MatchHistory!$J:$J,MATCH(1,(MatchHistory!$B:$B=$A36)*(MatchHistory!$J:$J<>""),0))} -> 1153
A37: Pinkee | B37: =COUNTIFS(MatchHistory!$B:$B, $A37, MatchHistory!$C:$C, "Town") -> 4 | C37: =COUNTIFS(MatchHistory!B:B, A37, MatchHistory!C:C, "Town", MatchHistory!D:D, "Win") -> 3 | D37: =IFERROR(__xludf.DUMMYFUNCTION("IF(EQ($B37, 0), TO_PERCENT(0), TO_PERCENT($C37/$B37))"),0.75) -> 0.75 | E37: =COUNTIFS(MatchHistory!$B:$B, $A37, MatchHistory!$C:$C, "Mafia") -> 0 | F37: =COUNTIFS(MatchHistory!$B:$B, $A37, MatchHistory!$C:$C, "Mafia", MatchHistory!$D:$D, "Win") -> 0 | G37: =IFERROR(__xludf.DUMMYFUNCTION("TO_PERCENT(IFERROR($F37/$E37, 0))"),0.0) -> 0 | H37: =SUM(E37, B37) -> 4 | I37: =IFERROR(__xludf.DUMMYFUNCTION("TO_PERCENT(IFERROR(($F37+$C37)/($E37+$B37), 0))"),0.75) -> 0.75 | J37: {=INDEX(MatchHistory!$G:$G,MATCH(1,(MatchHistory!$B:$B=$A37)*(MatchHistory!$G:$G<>""),0))} -> 28.706429 | K37: {=INDEX(MatchHistory!$H:$H,MATCH(1,(MatchHistory!$B:$B=$A37)*(MatchHistory!$H:$H<>""),0))} -> 8.0474698 | L37: {=INDEX(MatchHistory!$J:$J,MATCH(1,(MatchHistory!$B:$B=$A37)*(MatchHistory!$J:$J<>""),0))} -> 1131
A38: Starv | B38: =COUNTIFS(MatchHistory!$B:$B, $A38, MatchHistory!$C:$C, "Town") -> 4 | C38: =COUNTIFS(MatchHistory!B:B, A38, MatchHistory!C:C, "Town", MatchHistory!D:D, "Win") -> 3 | D38: =IFERROR(__xludf.DUMMYFUNCTION("IF(EQ($B38, 0), TO_PERCENT(0), TO_PERCENT($C38/$B38))"),0.75) -> 0.75 | E38: =COUNTIFS(MatchHistory!$B:$B, $A38, MatchHistory!$C:$C, "Mafia") -> 1 | F38: =COUNTIFS(MatchHistory!$B:$B, $A38, MatchHistory!$C:$C, "Mafia", MatchHistory!$D:$D, "Win") -> 1 | G38: =IFERROR(__xludf.DUMMYFUNCTION("TO_PERCENT(IFERROR($F38/$E38, 0))"),1.0) -> 1 | H38: =SUM(E38, B38) -> 5 | I38: =IFERROR(__xludf.DUMMYFUNCTION("TO_PERCENT(IFERROR(($F38+$C38)/($E38+$B38), 0))"),0.8) -> 0.8 | J38: {=INDEX(MatchHistory!$G:$G,MATCH(1,(MatchHistory!$B:$B=$A38)*(MatchHistory!$G:$G<>""),0))} -> 28.686871 | K38: {=INDEX(MatchHistory!$H:$H,MATCH(1,(MatchHistory!$B:$B=$A38)*(MatchHistory!$H:$H<>""),0))} -> 8.0497355 | L38: {=INDEX(MatchHistory!$J:$J,MATCH(1,(MatchHistory!$B:$B=$A38)*(MatchHistory!$J:$J<>""),0))} -> 1130
A39: Kny | B39: =COUNTIFS(MatchHistory!$B:$B, $A39, MatchHistory!$C:$C, "Town") -> 5 | C39: =COUNTIFS(MatchHistory!B:B, A39, MatchHistory!C:C, "Town", MatchHistory!D:D, "Win") -> 3 | D39: =IFERROR(__xludf.DUMMYFUNCTION("IF(EQ($B39, 0), TO_PERCENT(0), TO_PERCENT($C39/$B39))"),0.6) -> 0.6 | E39: =COUNTIFS(MatchHistory!$B:$B, $A39, MatchHistory!$C:$C, "Mafia") -> 1 | F39: =COUNTIFS(MatchHistory!$B:$B, $A39, MatchHistory!$C:$C, "Mafia", MatchHistory!$D:$D, "Win") -> 1 | G39: =IFERROR(__xludf.DUMMYFUNCTION("TO_PERCENT(IFERROR($F39/$E39, 0))"),1.0) -> 1 | H39: =SUM(E39, B39) -> 6 | I39: =IFERROR(__xludf.DUMMYFUNCTION("TO_PERCENT(IFERROR(($F39+$C39)/($E39+$B39), 0))"),0.6666666666666666) -> 0.66666667 | J39: {=INDEX(MatchHistory!$G:$G,MATCH(1,(MatchHistory!$B:$B=$A39)*(MatchHistory!$G:$G<>""),0))} -> 28.397631 | K39: {=INDEX(MatchHistory!$H:$H,MATCH(1,(MatchHistory!$B:$B=$A39)*(MatchHistory!$H:$H<>""),0))} -> 7.9967455 | L39: {=INDEX(MatchHistory!$J:$J,MATCH(1,(MatchHistory!$B:$B=$A39)*(MatchHistory!$J:$J<>""),0))} -> 1115
A40: striker | B40: =COUNTIFS(MatchHistory!$B:$B, $A40, MatchHistory!$C:$C, "Town") -> 5 | C40: =COUNTIFS(MatchHistory!B:B, A40, MatchHistory!C:C, "Town", MatchHistory!D:D, "Win") -> 2 | D40: =IFERROR(__xludf.DUMMYFUNCTION("IF(EQ($B40, 0), TO_PERCENT(0), TO_PERCENT($C40/$B40))"),0.4) -> 0.4 | E40: =COUNTIFS(MatchHistory!$B:$B, $A40, MatchHistory!$C:$C, "Mafia") -> 1 | F40: =COUNTIFS(MatchHistory!$B:$B, $A40, MatchHistory!$C:$C, "Mafia", MatchHistory!$D:$D, "Win") -> 1 | G40: =IFERROR(__xludf.DUMMYFUNCTION("TO_PERCENT(IFERROR($F40/$E40, 0))"),1.0) -> 1 | H40: =SUM(E40, B40) -> 6 | I40: =IFERROR(__xludf.DUMMYFUNCTION("TO_PERCENT(IFERROR(($F40+$C40)/($E40+$B40), 0))"),0.5) -> 0.5 | J40: {=INDEX(MatchHistory!$G:$G,MATCH(1,(MatchHistory!$B:$B=$A40)*(MatchHistory!$G:$G<>""),0))} -> 28.098609 | K40: {=INDEX(MatchHistory!$H:$H,MATCH(1,(MatchHistory!$B:$B=$A40)*(MatchHistory!$H:$H<>""),0))} -> 7.8968515 | L40: {=INDEX(MatchHistory!$J:$J,MATCH(1,(MatchHistory!$B:$B=$A40)*(MatchHistory!$J:$J<>""),0))} -> 1105
...

Sheet MatchRatings
B1: mu | C1: sigma
A2: Player | B2: mu | C2: sigma
A3: Jake | B3: 28.003534 | C3: 8.1263685
A4: Carson | B4: 30.325724 | C4: 5.7922464
A5: Creatchee | B5: 36.313279 | C5: 7.1623727
A6: Smit | B6: 21.22932 | C6: 5.9611702
A7: Boobles | B7: 28.045981 | C7: 7.8794217
A8: Badpants | B8: 27.412338 | C8: 5.4212107
A9: Kwix | B9: 24.106869 | C9: 6.3329078
A10: Chipper | B10: 31.980698 | C10: 5.8149377
A11: Machop | B11: 24.676032 | C11: 6.6723845
A12: Happymeal | B12: 22.192759 | C12: 7.2102474
A13: Lou | B13: 31.267898 | C13: 5.8569431
A14: Iln | B14: 31.816797 | C14: 5.238906
... A115: Siggywiggy | B115: 26.813244 | C115: 8.2349325

Sheet MatchHistory
A1: GameID | B1: Player | C1: Alignment | D1: Result | E1: RateChange | F1: old_mu | G1: new_mu | H1: new_sigma | I1: old_rating | J1: new_rating | K1: old_sigma
A2: 184 | B2: Josh | C2: Mafia | D2: Win | E2: 39 | F2: 28.464169 | G2: 28.979614 | H2: 7.2783272 | I2: 1189 | J2: 1228 | K2: 7.3237986
A3: 184 | B3: Laur | C3: Mafia | D3: Win | E3: 25 | F3: 35.148769 | G3: 35.476764 | H3: 5.8193791 | I3: 1794 | J3: 1819 | K3: 5.8419245
A4: 184 | B4: Chipper | C4: Mafia | D4: Win | E4: 25 | F4: 31.653207 | G4: 31.980698 | H4: 5.8149377 | I4: 1557 | J4: 1582 | K4: 5.8374284
A5: 184 | B5: Iln | C5: Town | D5: Loss | E5: -17 | F5: 32.082214 | G5: 31.816797 | H5: 5.238906 | I5: 1646 | J5: 1629 | K5: 5.2549826
A6: 184 | B6: Strik3r | C6: Town | D6: Loss | E6: -25 | F6: 29.052177 | G6: 28.631602 | H6: 6.5821928 | I6: 1301 | J6: 1276 | K6: 6.6154349
A7: 184 | B7: Brownkow | C7: Town | D7: Loss | E7: -17 | F7: 31.64143 | G7: 31.363469 | H7: 5.3604515 | I7: 1603 | J7: 1586 | K7: 5.3777725
A8: 184 | B8: Kden | C8: Town | D8: Loss | E8: -22 | F8: 28.670135 | G8: 28.313355 | H8: 6.0672109 | I8: 1328 | J8: 1306 | K8: 6.0929433
A9: 184 | B9: Noah | C9: Town | D9: Loss | E9: -21 | F9: 35.086537 | G9: 34.73979 | H9: 5.9820323 | I9: 1773 | J9: 1752 | K9: 6.0066392
A10: 184 | B10: Levi | C10: Town | D10: Loss | E10: -35 | F10: 26.187691 | G10: 25.570623 | H10: 7.9535653 | I10: 963 | J10: 928 | K10: 8.013435
A11: 184 | B11: Chelsea | C11: Town | D11: Loss | E11: -24 | F11: 30.773129 | G11: 30.385304 | H11: 6.3232698 | I11: 1445 | J11: 1421 | K11: 6.3525817
A12: 184 | B12: Kwix | C12: Town | D12: Loss | E12: -24 | F12: 24.495889 | G12: 24.106869 | H12: 6.3329078 | I12: 1017 | J12: 993 | K12: 6.3623603
A13: 184 | B13: Ghost | C13: Town | D13: Ghost | E13: 0
A14: 184 | B14: Ken | C14: Town | D14: Night Zero | E14: 0
A15: 184 | B15: Rocker | C15: Town | D15: Loss | E15: -17 | F15: 37.010185 | G15: 36.736488 | H15: 5.3194585 | I15: 1972 | J15: 1955 | K15: 5.3363535
A16: 184 | B16: Carson | C16: Town | D16: Loss | E16: -20 | F16: 30.650644 | G16: 30.325724 | H16: 5.7922464 | I16: 1491 | J16: 1471 | K16: 5.8144589
A17: 183 | B17: Motr | C17: Mafia | D17: Win | E17: 64 | F17: 27.03273 | G17: 27.910313 | H17: 6.6196349 | I17: 1159 | J17: 1223 | K17: 6.6614165
A18: 183 | B18: Hunter | C18: Mafia | D18: Win | E18: 86 | F18: 24.877739 | G18: 26.038543 | H18: 7.5973829 | I18: 910 | J18: 996 | K18: 7.6615003
A19: 183 | B19: striker | C19: Mafia | D19: Win | E19: 93 | F19: 26.842729 | G19: 28.098609 | H19: 7.8968515 | I19: 1012 | J19: 1105 | K19: 7.9691379
A20: 183 | B20: Smit | C20: Town | D20: Night Zero | E20: 0
A21: 183 | B21: Brownkow | C21: Town | D21: Loss | E21: -37 | F21: 32.218076 | G21: 31.64143 | H21: 5.3777725 | I21: 1640 | J21: 1603 | K21: 5.3994759
A22: 183 | B22: Chipper | C22: Town | D22: Loss | E22: -43 | F22: 32.333675 | G22: 31.653207 | H22: 5.8374284 | I22: 1600 | J22: 1557 | K22: 5.8655951
A23: 183 | B23: Machop | C23: Town | D23: Loss | E23: -57 | F23: 25.567844 | G23: 24.676032 | H23: 6.6723845 | I23: 1054 | J23: 997 | K23: 6.7152129
A24: 183 | B24: Kwix | C24: Town | D24: Loss | E24: -51 | F24: 25.305778 | G24: 24.495889 | H24: 6.3623603 | I24: 1068 | J24: 1017 | K24: 6.3992767
A25: 183 | B25: Gilbert | C25: Town | D25: Loss | E25: -53 | F25: 31.164828 | G25: 30.32656 | H25: 6.471524 | I25: 1455 | J25: 1402 | K25: 6.5104565
A26: 183 | B26: Svaan | C26: Town | D26: Loss | E26: -57 | F26: 28.819978 | G26: 27.920206 | H26: 6.7017035 | I26: 1272 | J26: 1215 | K26: 6.7451211
A27: 183 | B27: Matt (Decode) | C27: Town | D27: Loss | E27: -62 | F27: 22.28627 | G27: 21.299736 | H27: 7.0129051 | I27: 795 | J27: 733 | K27: 7.062911
A28: 183 | B28: Double A | C28: Town | D28: Loss | E28: -82 | F28: 23.515499 | G28: 22.178438 | H28: 8.1431934 | I28: 760 | J28: 678 | K28: 8.2227058
A29: 183 | B29: Iln | C29: Town | D29: Loss | E29: -35 | F29: 32.632617 | G29: 32.082214 | H29: 5.2549826 | I29: 1681 | J29: 1646 | K29: 5.275135
A30: 183 | B30: Lou | C30: Town | D30: Loss | E30: -43 | F30: 31.952969 | G30: 31.267898 | H30: 5.8569431 | I30: 1572 | J30: 1529 | K30: 5.8854081
A31: 183 | B31: Laur | C31: Town | D31: Loss | E31: -44 | F31: 35.830296 | G31: 35.148769 | H31: 5.8419245 | I31: 1838 | J31: 1794 | K31: 5.8701597
A32: 182 | B32: Chipper | C32: Mafia | D32: Loss | E32: -76 | F32: 33.503212 | G32: 32.333675 | H32: 5.8655951 | I32: 1676 | J32: 1600 | K32: 5.9053632
... A36: 182 | B36: Ken | C36: Town | D36: Win | E36: 103 | F36: 25.247062 | G36: 26.680961 | H36: 6.4845692 | I36: 1050 | J36: 1153 | K36: 6.5389844
A37: 182 | B37: Ghost | C37: Town | D37: Ghost | E37: 0
A38: 182 | B38: Matt | C38: Town | D38: Win | E38: 146 | F38: 30.954991 | G38: 32.960848 | H38: 7.6433982 | I38: 1316 | J38: 1462 | K38: 7.7342036
A39: 182 | B39: Laur | C39: Town | D39: Win | E39: 84 | F39: 34.658913 | G39: 35.830296 | H39: 5.8701597 | I39: 1754 | J39: 1838 | K39: 5.9100249
A40: 182 | B40: Gilbert | C40: Town | D40: Win | E40: 104 | F40: 29.719257 | G40: 31.164828 | H40: 6.5104565 | I40: 1351 | J40: 1455 | K40: 6.565552
A41: 182 | B41: Svaan | C41: Town | D41: Win | E41: 112 | F41: 27.266318 | G41: 28.819978 | H41: 6.7451211 | I41: 1160 | J41: 1272 | K41: 6.8066441
A42: 182 | B42: Keegan | C42: Town | D42: Win | E42: 130 | F42: 28.30696 | G42: 30.105009 | H42: 7.2456647 | I42: 1178 | J42: 1308 | K42: 7.3225487
A43: 182 | B43: Streety | C43: Town | D43: Win | E43: 104 | F43: 29.574379 | G43: 31.0274 | H43: 6.5269233 | I43: 1340 | J43: 1444 | K43: 6.5824544
...

Sheet Season 1 - Stats Summary
A1: Name | B1: Town Games | C1: Town Wins | D1: Town Win % | E1: Mafia Games | F1: Mafia Wins | G1: Mafia Win % | H1: Total Win % | I1: Mu | J1: Sigma | K1: Rating
A2: Machop | B2: =COUNTIFS('Season 1 - MatchHistory'!$B:$B, $A2, 'Season 1 - MatchHistory'!$C:$C, "Town") -> 34 | C2: =COUNTIFS('Season 1 - MatchHistory'!B:B, A2, 'Season 1 - MatchHistory'!C:C, "Town", 'Season 1 - MatchHistory'!D:D, "Win") -> 16 | D2: =IFERROR(__xludf.DUMMYFUNCTION("IF(EQ($B2, 0), TO_PERCENT(0), TO_PERCENT($C2/$B2))"),0.47058823529411764) -> 0.47058824 | E2: =COUNTIFS('Season 1 - MatchHistory'!$B:$B, $A2, 'Season 1 - MatchHistory'!$C:$C, "Mafia") -> 6 | F2: =COUNTIFS('Season 1 - MatchHistory'!$B:$B, $A2, 'Season 1 - MatchHistory'!$C:$C, "Mafia", 'Season 1 - MatchHistory'!$D:$D, "Win") -> 6 | G2: =IFERROR(__xludf.DUMMYFUNCTION("TO_PERCENT(IFERROR($F2/$E2, 0))"),1.0) -> 1 | H2: =IFERROR(__xludf.DUMMYFUNCTION("TO_PERCENT(IFERROR(($F2+$C2)/($E2+$B2), 0))"),0.55) -> 0.55 | I2: {=INDEX('Season 1 - MatchHistory'!$G:$G,MATCH(1,('Season 1 - MatchHistory'!$B:$B=$A2)*('Season 1 - MatchHistory'!$G:$G<>""),0))} -> 33.259148 | J2: {=INDEX('Season 1 - MatchHistory'!$H:$H,MATCH(1,('Season 1 - MatchHistory'!$B:$B=$A2)*('Season 1 - MatchHistory'!$H:$H<>""),0))} -> 6.7512772 | K2: {=INDEX('Season 1 - MatchHistory'!$J:$J,MATCH(1,('Season 1 - MatchHistory'!$B:$B=$A2)*('Season 1 - MatchHistory'!$J:$J<>""),0))} -> 1573
A3: Maz | B3: =COUNTIFS('Season 1 - MatchHistory'!$B:$B, $A3, 'Season 1 - MatchHistory'!$C:$C, "Town") -> 15 | C3: =COUNTIFS('Season 1 - MatchHistory'!B:B, A3, 'Season 1 - MatchHistory'!C:C, "Town", 'Season 1 - MatchHistory'!D:D, "Win") -> 7 | D3: =IFERROR(__xludf.DUMMYFUNCTION("IF(EQ($B3, 0), TO_PERCENT(0), TO_PERCENT($C3/$B3))"),0.4666666666666667) -> 0.46666667 | E3: =COUNTIFS('Season 1 - MatchHistory'!$B:$B, $A3, 'Season 1 - MatchHistory'!$C:$C, "Mafia") -> 7 | F3: =COUNTIFS('Season 1 - MatchHistory'!$B:$B, $A3, 'Season 1 - MatchHistory'!$C:$C, "Mafia", 'Season 1 - MatchHistory'!$D:$D, "Win") -> 7 | G3: =IFERROR(__xludf.DUMMYFUNCTION("TO_PERCENT(IFERROR($F3/$E3, 0))"),1.0) -> 1 | H3: =IFERROR(__xludf.DUMMYFUNCTION("TO_PERCENT(IFERROR(($F3+$C3)/($E3+$B3), 0))"),0.6363636363636364) -> 0.63636364 | I3: {=INDEX('Season 1 - MatchHistory'!$G:$G,MATCH(1,('Season 1 - MatchHistory'!$B:$B=$A3)*('Season 1 - MatchHistory'!$G:$G<>""),0))} -> 31.79948 | J3: {=INDEX('Season 1 - MatchHistory'!$H:$H,MATCH(1,('Season 1 - MatchHistory'!$B:$B=$A3)*('Season 1 - MatchHistory'!$H:$H<>""),0))} -> 7.3351158 | K3: {=INDEX('Season 1 - MatchHistory'!$J:$J,MATCH(1,('Season 1 - MatchHistory'!$B:$B=$A3)*('Season 1 - MatchHistory'!$J:$J<>""),0))} -> 1414
A4: Boobles | B4: =COUNTIFS('Season 1 - MatchHistory'!$B:$B, $A4, 'Season 1 - MatchHistory'!$C:$C, "Town") -> 11 | C4: =COUNTIFS('Season 1 - MatchHistory'!B:B, A4, 'Season 1 - MatchHistory'!C:C, "Town", 'Season 1 - MatchHistory'!D:D, "Win") -> 7 | D4: =IFERROR(__xludf.DUMMYFUNCTION("IF(EQ($B4, 0), TO_PERCENT(0), TO_PERCENT($C4/$B4))"),0.6363636363636364) -> 0.63636364 | E4: =COUNTIFS('Season 1 - MatchHistory'!$B:$B, $A4, 'Season 1 - MatchHistory'!$C:$C, "Mafia") -> 1 | F4: =COUNTIFS('Season 1 - MatchHistory'!$B:$B, $A4, 'Season 1 - MatchHistory'!$C:$C, "Mafia", 'Season 1 - MatchHistory'!$D:$D, "Win") -> 1 | G4: =IFERROR(__xludf.DUMMYFUNCTION("TO_PERCENT(IFERROR($F4/$E4, 0))"),1.0) -> 1 | H4: =IFERROR(__xludf.DUMMYFUNCTION("TO_PERCENT(IFERROR(($F4+$C4)/($E4+$B4), 0))"),0.6666666666666666) -> 0.66666667 | I4: {=INDEX('Season 1 - MatchHistory'!$G:$G,MATCH(1,('Season 1 - MatchHistory'!$B:$B=$A4)*('Season 1 - MatchHistory'!$G:$G<>""),0))} -> 31.73429 | J4: {=INDEX('Season 1 - MatchHistory'!$H:$H,MATCH(1,('Season 1 - MatchHistory'!$B:$B=$A4)*('Season 1 - MatchHistory'!$H:$H<>""),0))} -> 7.7129871 | K4: {=INDEX('Season 1 - MatchHistory'!$J:$J,MATCH(1,('Season 1 - MatchHistory'!$B:$B=$A4)*('Season 1 - MatchHistory'!$J:$J<>""),0))} -> 1371
A5: Noah | B5: =COUNTIFS('Season 1 - MatchHistory'!$B:$B, $A5, 'Season 1 - MatchHistory'!$C:$C, "Town") -> 26 | C5: =COUNTIFS('Season 1 - MatchHistory'!B:B, A5, 'Season 1 - MatchHistory'!C:C, "Town", 'Season 1 - MatchHistory'!D:D, "Win") -> 11 | D5: =IFERROR(__xludf.DUMMYFUNCTION("IF(EQ($B5, 0), TO_PERCENT(0), TO_PERCENT($C5/$B5))"),0.4230769230769231) -> 0.42307692 | E5: =COUNTIFS('Season 1 - MatchHistory'!$B:$B, $A5, 'Season 1 - MatchHistory'!$C:$C, "Mafia") -> 12 | F5: =COUNTIFS('Season 1 - MatchHistory'!$B:$B, $A5, 'Season 1 - MatchHistory'!$C:$C, "Mafia", 'Season 1 - MatchHistory'!$D:$D, "Win") -> 10 | G5: =IFERROR(__xludf.DUMMYFUNCTION("TO_PERCENT(IFERROR($F5/$E5, 0))"),0.8333333333333334) -> 0.83333333 | H5: =IFERROR(__xludf.DUMMYFUNCTION("TO_PERCENT(IFERROR(($F5+$C5)/($E5+$B5), 0))"),0.5526315789473685) -> 0.55263158 | I5: {=INDEX('Season 1 - MatchHistory'!$G:$G,MATCH(1,('Season 1 - MatchHistory'!$B:$B=$A5)*('Season 1 - MatchHistory'!$G:$G<>""),0))} -> 29.545123 | J5: {=INDEX('Season 1 - MatchHistory'!$H:$H,MATCH(1,('Season 1 - MatchHistory'!$B:$B=$A5)*('Season 1 - MatchHistory'!$H:$H<>""),0))} -> 6.8075592 | K5: {=INDEX('Season 1 - MatchHistory'!$J:$J,MATCH(1,('Season 1 - MatchHistory'!$B:$B=$A5)*('Season 1 - MatchHistory'!$J:$J<>""),0))} -> 1315
A6: Rick | B6: =COUNTIFS('Season 1 - MatchHistory'!$B:$B, $A6, 'Season 1 - MatchHistory'!$C:$C, "Town") -> 5 | C6: =COUNTIFS('Season 1 - MatchHistory'!B:B, A6, 'Season 1 - MatchHistory'!C:C, "Town", 'Season 1 - MatchHistory'!D:D, "Win") -> 4 | D6: =IFERROR(__xludf.DUMMYFUNCTION("IF(EQ($B6, 0), TO_PERCENT(0), TO_PERCENT($C6/$B6))"),0.8) -> 0.8 | E6: =COUNTIFS('Season 1 - MatchHistory'!$B:$B, $A6, 'Season 1 - MatchHistory'!$C:$C, "Mafia") -> 1 | F6: =COUNTIFS('Season 1 - MatchHistory'!$B:$B, $A6, 'Season 1 - MatchHistory'!$C:$C, "Mafia", 'Season 1 - MatchHistory'!$D:$D, "Win") -> 1 | G6: =IFERROR(__xludf.DUMMYFUNCTION("TO_PERCENT(IFERROR($F6/$E6, 0))"),1.0) -> 1 | H6: =IFERROR(__xludf.DUMMYFUNCTION("TO_PERCENT(IFERROR(($F6+$C6)/($E6+$B6), 0))"),0.8333333333333334) -> 0.83333333 | I6: {=INDEX('Season 1 - MatchHistory'!$G:$G,MATCH(1,('Season 1 - MatchHistory'!$B:$B=$A6)*('Season 1 - MatchHistory'!$G:$G<>""),0))} -> 29.762849 | J6: {=INDEX('Season 1 - MatchHistory'!$H:$H,MATCH(1,('Season 1 - MatchHistory'!$B:$B=$A6)*('Season 1 - MatchHistory'!$H:$H<>""),0))} -> 7.9921747 | K6: {=INDEX('Season 1 - MatchHistory'!$J:$J,MATCH(1,('Season 1 - MatchHistory'!$B:$B=$A6)*('Season 1 - MatchHistory'!$J:$J<>""),0))} -> 1209
A7: Keegan | B7: =COUNTIFS('Season 1 - MatchHistory'!$B:$B, $A7, 'Season 1 - MatchHistory'!$C:$C, "Town") -> 15 | C7: =COUNTIFS('Season 1 - MatchHistory'!B:B, A7, 'Season 1 - MatchHistory'!C:C, "Town", 'Season 1 - MatchHistory'!D:D, "Win") -> 7 | D7: =IFERROR(__xludf.DUMMYFUNCTION("IF(EQ($B7, 0), TO_PERCENT(0), TO_PERCENT($C7/$B7))"),0.4666666666666667) -> 0.46666667 | E7: =COUNTIFS('Season 1 - MatchHistory'!$B:$B, $A7, 'Season 1 - MatchHistory'!$C:$C, "Mafia") -> 2 | F7: =COUNTIFS('Season 1 - MatchHistory'!$B:$B, $A7, 'Season 1 - MatchHistory'!$C:$C, "Mafia", 'Season 1 - MatchHistory'!$D:$D, "Win") -> 2 | G7: =IFERROR(__xludf.DUMMYFUNCTION("TO_PERCENT(IFERROR($F7/$E7, 0))"),1.0) -> 1 | H7: =IFERROR(__xludf.DUMMYFUNCTION("TO_PERCENT(IFERROR(($F7+$C7)/($E7+$B7), 0))"),0.5294117647058824) -> 0.52941176 | I7: {=INDEX('Season 1 - MatchHistory'!$G:$G,MATCH(1,('Season 1 - MatchHistory'!$B:$B=$A7)*('Season 1 - MatchHistory'!$G:$G<>""),0))} -> 28.331162 | J7: {=INDEX('Season 1 - MatchHistory'!$H:$H,MATCH(1,('Season 1 - MatchHistory'!$B:$B=$A7)*('Season 1 - MatchHistory'!$H:$H<>""),0))} -> 7.5352168 | K7: {=INDEX('Season 1 - MatchHistory'!$J:$J,MATCH(1,('Season 1 - MatchHistory'!$B:$B=$A7)*('Season 1 - MatchHistory'!$J:$J<>""),0))} -> 1158
A8: Mintt | B8: =COUNTIFS('Season 1 - MatchHistory'!$B:$B, $A8, 'Season 1 - MatchHistory'!$C:$C, "Town") -> 4 | C8: =COUNTIFS('Season 1 - MatchHistory'!B:B, A8, 'Season 1 - MatchHistory'!C:C, "Town", 'Season 1 - MatchHistory'!D:D, "Win") -> 3 | D8: =IFERROR(__xludf.DUMMYFUNCTION("IF(EQ($B8, 0), TO_PERCENT(0), TO_PERCENT($C8/$B8))"),0.75) -> 0.75 | E8: =COUNTIFS('Season 1 - MatchHistory'!$B:$B, $A8, 'Season 1 - MatchHistory'!$C:$C, "Mafia") -> 1 | F8: =COUNTIFS('Season 1 - MatchHistory'!$B:$B, $A8, 'Season 1 - MatchHistory'!$C:$C, "Mafia", 'Season 1 - MatchHistory'!$D:$D, "Win") -> 1 | G8: =IFERROR(__xludf.DUMMYFUNCTION("TO_PERCENT(IFERROR($F8/$E8, 0))"),1.0) -> 1 | H8: =IFERROR(__xludf.DUMMYFUNCTION("TO_PERCENT(IFERROR(($F8+$C8)/($E8+$B8), 0))"),0.8) -> 0.8 | I8: {=INDEX('Season 1 - MatchHistory'!$G:$G,MATCH(1,('Season 1 - MatchHistory'!$B:$B=$A8)*('Season 1 - MatchHistory'!$G:$G<>""),0))} -> 28.61669 | J8: {=INDEX('Season 1 - MatchHistory'!$H:$H,MATCH(1,('Season 1 - MatchHistory'!$B:$B=$A8)*('Season 1 - MatchHistory'!$H:$H<>""),0))} -> 8.0578385 | K8: {=INDEX('Season 1 - MatchHistory'!$J:$J,MATCH(1,('Season 1 - MatchHistory'!$B:$B=$A8)*('Season 1 - MatchHistory'!$J:$J<>""),0))} -> 1124
A9: Badpants | B9: =COUNTIFS('Season 1 - MatchHistory'!$B:$B, $A9, 'Season 1 - MatchHistory'!$C:$C, "Town") -> 2 | C9: =COUNTIFS('Season 1 - MatchHistory'!B:B, A9, 'Season 1 - MatchHistory'!C:C, "Town", 'Season 1 - MatchHistory'!D:D, "Win") -> 2 | D9: =IFERROR(__xludf.DUMMYFUNCTION("IF(EQ($B9, 0), TO_PERCENT(0), TO_PERCENT($C9/$B9))"),1.0) -> 1 | E9: =COUNTIFS('Season 1 - MatchHistory'!$B:$B, $A9, 'Season 1 - MatchHistory'!$C:$C, "Mafia") -> 3 | F9: =COUNTIFS('Season 1 - MatchHistory'!$B:$B, $A9, 'Season 1 - MatchHistory'!$C:$C, "Mafia", 'Season 1 - MatchHistory'!$D:$D, "Win") -> 2 | G9: =IFERROR(__xludf.DUMMYFUNCTION("TO_PERCENT(IFERROR($F9/$E9, 0))"),0.6666666666666666) -> 0.66666667 | H9: =IFERROR(__xludf.DUMMYFUNCTION("TO_PERCENT(IFERROR(($F9+$C9)/($E9+$B9), 0))"),0.8) -> 0.8 | I9: {=INDEX('Season 1 - MatchHistory'!$G:$G,MATCH(1,('Season 1 - MatchHistory'!$B:$B=$A9)*('Season 1 - MatchHistory'!$G:$G<>""),0))} -> 28.221384 | J9: {=INDEX('Season 1 - MatchHistory'!$H:$H,MATCH(1,('Season 1 - MatchHistory'!$B:$B=$A9)*('Season 1 - MatchHistory'!$H:$H<>""),0))} -> 8.0569493 | K9: {=INDEX('Season 1 - MatchHistory'!$J:$J,MATCH(1,('Season 1 - MatchHistory'!$B:$B=$A9)*('Season 1 - MatchHistory'!$J:$J<>""),0))} -> 1097
A10: Xcync | B10: =COUNTIFS('Season 1 - MatchHistory'!$B:$B, $A10, 'Season 1 - MatchHistory'!$C:$C, "Town") -> 6 | C10: =COUNTIFS('Season 1 - MatchHistory'!B:B, A10, 'Season 1 - MatchHistory'!C:C, "Town", 'Season 1 - MatchHistory'!D:D, "Win") -> 4 | D10: =IFERROR(__xludf.DUMMYFUNCTION("IF(EQ($B10, 0), TO_PERCENT(0), TO_PERCENT($C10/$B10))"),0.6666666666666666) -> 0.66666667 | E10: =COUNTIFS('Season 1 - MatchHistory'!$B:$B, $A10, 'Season 1 - MatchHistory'!$C:$C, "Mafia") -> 1 | F10: =COUNTIFS('Season 1 - MatchHistory'!$B:$B, $A10, 'Season 1 - MatchHistory'!$C:$C, "Mafia", 'Season 1 - MatchHistory'!$D:$D, "Win") -> 0 | G10: =IFERROR(__xludf.DUMMYFUNCTION("TO_PERCENT(IFERROR($F10/$E10, 0))"),0.0) -> 0 | H10: =IFERROR(__xludf.DUMMYFUNCTION("TO_PERCENT(IFERROR(($F10+$C10)/($E10+$B10), 0))"),0.5714285714285714) -> 0.57142857 | I10: {=INDEX('Season 1 - MatchHistory'!$G:$G,MATCH(1,('Season 1 - MatchHistory'!$B:$B=$A10)*('Season 1 - MatchHistory'!$G:$G<>""),0))} -> 27.871124 | J10: {=INDEX('Season 1 - MatchHistory'!$H:$H,MATCH(1,('Season 1 - MatchHistory'!$B:$B=$A10)*('Season 1 - MatchHistory'!$H:$H<>""),0))} -> 7.9318011 | K10: {=INDEX('Season 1 - MatchHistory'!$J:$J,MATCH(1,('Season 1 - MatchHistory'!$B:$B=$A10)*('Season 1 - MatchHistory'!$J:$J<>""),0))} -> 1086
