Workbook

Sheet Introduction
A1: Welcome to the ELO Mafia Rankings Leaderboard!
A3: How to use this sheet: Start with the Stats Summary tab. This will give you your win rates, your 'sigma' and 'mu' (see FAQ) and, most importantly, your Elo. The FAQ explains how the ratings are calculated, among other things, so if you want to figure out how to reverse engineer everything head over there to take a look. The MatchHistory tab shows how your stats are calculated on a game-by-game basis. The MafiaRatings tab is where we calculate your 'sigma' and 'mu', but probably isn't terribly useful unless you're really interested in getting down into the fine details.
A12: FAQ
A19: If you find an error, like two rankings for the same player, etc., tell Brown Kow in Discord

Sheet Stats Summary
A1: Name | B1: Town Games | C1: Town Wins | D1: Town % | E1: Town Win % | F1: Mafia Games | G1: Mafia Wins | H1: Mafia % | I1: Mafia Win % | J1: Total Games | K1: Total Win % | L1: Mu | M1: Sigma | N1: Rating
A2: Rocker | B2: =COUNTIFS(MatchHistory!$B:$B, $A2, MatchHistory!$C:$C, "Town") | C2: =COUNTIFS(MatchHistory!B:B, A2, MatchHistory!C:C, "Town", MatchHistory!D:D, "Win") | D2: =IFERROR(__xludf.DUMMYFUNCTION("TO_PERCENT($B2/$J2)"),0.7777777777777778) | E2: =IFERROR(__xludf.DUMMYFUNCTION("IF(EQ($B2, 0), TO_PERCENT(0), TO_PERCENT($C2/$B2))"),0.5714285714285714) | F2: =COUNTIFS(MatchHistory!$B:$B, $A2, MatchHistory!$C:$C, "Mafia") | G2: =COUNTIFS(MatchHistory!$B:$B, $A2, MatchHistory!$C:$C, "Mafia", MatchHistory!$D:$D, "Win") | H2: =IFERROR(__xludf.DUMMYFUNCTION("TO_PERCENT($F2/$J2)"),0.2222222222222222) | I2: =IFERROR(__xludf.DUMMYFUNCTION("TO_PERCENT(IFERROR($G2/$F2, 0))"),0.625) | J2: =SUM(F2, B2) | K2: =IFERROR(__xludf.DUMMYFUNCTION("TO_PERCENT(IFERROR(($G2+$C2)/($F2+$B2), 0))"),0.5833333333333334) | L2: {=INDEX(MatchHistory!$G:$G,MATCH(1,(MatchHistory!$B:$B=$A2)*(MatchHistory!$G:$G<>""),0))} | M2: {=INDEX(MatchHistory!$H:$H,MATCH(1,(MatchHistory!$B:$B=$A2)*(MatchHistory!$H:$H<>""),0))} | N2: {=INDEX(MatchHistory!$J:$J,MATCH(1,(MatchHistory!$B:$B=$A2)*(MatchHistory!$J:$J<>""),0))}
A3: Cyclone | B3: =COUNTIFS(MatchHistory!$B:$B, $A3, MatchHistory!$C:$C, "Town") | C3: =COUNTIFS(MatchHistory!B:B, A3, MatchHistory!C:C, "Town", MatchHistory!D:D, "Win") | D3: =IFERROR(__xludf.DUMMYFUNCTION("TO_PERCENT($B3/$J3)"),0.8095238095238095) | E3: =IFERROR(__xludf.DUMMYFUNCTION("IF(EQ($B3, 0), TO_PERCENT(0), TO_PERCENT($C3/$B3))"),0.7058823529411765) | F3: =COUNTIFS(MatchHistory!$B:$B, $A3, MatchHistory!$C:$C, "Mafia") | G3: =COUNTIFS(MatchHistory!$B:$B, $A3, MatchHistory!$C:$C, "Mafia", MatchHistory!$D:$D, "Win") | H3: =IFERROR(__xludf.DUMMYFUNCTION("TO_PERCENT($F3/$J3)"),0.19047619047619047) | I3: =IFERROR(__xludf.DUMMYFUNCTION("TO_PERCENT(IFERROR($G3/$F3, 0))"),1.0) | J3: =SUM(F3, B3) | K3: =IFERROR(__xludf.DUMMYFUNCTION("TO_PERCENT(IFERROR(($G3+$C3)/($F3+$B3), 0))"),0.7619047619047619) | L3: {=INDEX(MatchHistory!$G:$G,MATCH(1,(MatchHistory!$B:$B=$A3)*(MatchHistory!$G:$G<>""),0))} | M3: {=INDEX(MatchHistory!$H:$H,MATCH(1,(MatchHistory!$B:$B=$A3)*(MatchHistory!$H:$H<>""),0))} | N3: {=INDEX(MatchHistory!$J:$J,MATCH(1,(MatchHistory!$B:$B=$A3)*(MatchHistory!$J:$J<>""),0))}
A4: Laur | B4: =COUNTIFS(MatchHistory!$B:$B, $A4, MatchHistory!$C:$C, "Town") | C4: =COUNTIFS(MatchHistory!B:B, A4, MatchHistory!C:C, "Town", MatchHistory!D:D, "Win") | D4: =IFERROR(__xludf.DUMMYFUNCTION("TO_PERCENT($B4/$J4)"),0.8076923076923077) | E4: =IFERROR(__xludf.DUMMYFUNCTION("IF(EQ($B4, 0), TO_PERCENT(0), TO_PERCENT($C4/$B4))"),0.5476190476190477) | F4: =COUNTIFS(MatchHistory!$B:$B, $A4, MatchHistory!$C:$C, "Mafia") | G4: =COUNTIFS(MatchHistory!$B:$B, $A4, MatchHistory!$C:$C, "Mafia", MatchHistory!$D:$D, "Win") | H4: =IFERROR(__xludf.DUMMYFUNCTION("TO_PERCENT($F4/$J4)"),0.19230769230769232) | I4: =IFERROR(__xludf.DUMMYFUNCTION("TO_PERCENT(IFERROR($G4/$F4, 0))"),0.7) | J4: =SUM(F4, B4) | K4: =IFERROR(__xludf.DUMMYFUNCTION("TO_PERCENT(IFERROR(($G4+$C4)/($F4+$B4), 0))"),0.5769230769230769) | L4: {=INDEX(MatchHistory!$G:$G,MATCH(1,(MatchHistory!$B:$B=$A4)*(MatchHistory!$G:$G<>""),0))} | M4: {=INDEX(MatchHistory!$H:$H,MATCH(1,(MatchHistory!$B:$B=$A4)*(MatchHistory!$H:$H<>""),0))} | N4: {=INDEX(MatchHistory!$J:$J,MATCH(1,(MatchHistory!$B:$B=$A4)*(MatchHistory!$J:$J<>""),0))}
A5: Rollo | B5: =COUNTIFS(MatchHistory!$B:$B, $A5, MatchHistory!$C:$C, "Town") | C5: =COUNTIFS(MatchHistory!B:B, A5, MatchHistory!C:C, "Town", MatchHistory!D:D, "Win") | D5: =IFERROR(__xludf.DUMMYFUNCTION("TO_PERCENT($B5/$J5)"),0.7058823529411765) | E5: =IFERROR(__xludf.DUMMYFUNCTION("IF(EQ($B5, 0), TO_PERCENT(0), TO_PERCENT($C5/$B5))"),0.75) | F5: =COUNTIFS(MatchHistory!$B:$B, $A5, MatchHistory!$C:$C, "Mafia") | G5: =COUNTIFS(MatchHistory!$B:$B, $A5, MatchHistory!$C:$C, "Mafia", MatchHistory!$D:$D, "Win") | H5: =IFERROR(__xludf.DUMMYFUNCTION("TO_PERCENT($F5/$J5)"),0.29411764705882354) | I5: =IFERROR(__xludf.DUMMYFUNCTION("TO_PERCENT(IFERROR($G5/$F5, 0))"),0.5) | J5: =SUM(F5, B5) | K5: =IFERROR(__xludf.DUMMYFUNCTION("TO_PERCENT(IFERROR(($G5+$C5)/($F5+$B5), 0))"),0.6764705882352942) | L5: {=INDEX(MatchHistory!$G:$G,MATCH(1,(MatchHistory!$B:$B=$A5)*(MatchHistory!$G:$G<>""),0))} | M5: {=INDEX(MatchHistory!$H:$H,MATCH(1,(MatchHistory!$B:$B=$A5)*(MatchHistory!$H:$H<>""),0))} | N5: {=INDEX(MatchHistory!$J:$J,MATCH(1,(MatchHistory!$B:$B=$A5)*(MatchHistory!$J:$J<>""),0))}
A6: Creatchee | B6: =COUNTIFS(MatchHistory!$B:$B, $A6, MatchHistory!$C:$C, "Town") | C6: =COUNTIFS(MatchHistory!B:B, A6, MatchHistory!C:C, "Town", MatchHistory!D:D, "Win") | D6: =IFERROR(__xludf.DUMMYFUNCTION("TO_PERCENT($B6/$J6)"),0.875) | E6: =IFERROR(__xludf.DUMMYFUNCTION("IF(EQ($B6, 0), TO_PERCENT(0), TO_PERCENT($C6/$B6))"),0.7142857142857143) | F6: =COUNTIFS(MatchHistory!$B:$B, $A6, MatchHistory!$C:$C, "Mafia") | G6: =COUNTIFS(MatchHistory!$B:$B, $A6, MatchHistory!$C:$C, "Mafia", MatchHistory!$D:$D, "Win") | H6: =IFERROR(__xludf.DUMMYFUNCTION("TO_PERCENT($F6/$J6)"),0.125) | I6: =IFERROR(__xludf.DUMMYFUNCTION("TO_PERCENT(IFERROR($G6/$F6, 0))"),0.6666666666666666) | J6: =SUM(F6, B6) | K6: =IFERROR(__xludf.DUMMYFUNCTION("TO_PERCENT(IFERROR(($G6+$C6)/($F6+$B6), 0))"),0.7083333333333334) | L6: {=INDEX(MatchHistory!$G:$G,MATCH(1,(MatchHistory!$B:$B=$A6)*(MatchHistory!$G:$G<>""),0))} | M6: {=INDEX(MatchHistory!$H:$H,MATCH(1,(MatchHistory!$B:$B=$A6)*(MatchHistory!$H:$H<>""),0))} | N6: {=INDEX(MatchHistory!$J:$J,MATCH(1,(MatchHistory!$B:$B=$A6)*(MatchHistory!$J:$J<>""),0))}
A7: Noah | B7: =COUNTIFS(MatchHistory!$B:$B, $A7, MatchHistory!$C:$C, "Town") | C7: =COUNTIFS(MatchHistory!B:B, A7, MatchHistory!C:C, "Town", MatchHistory!D:D, "Win") | D7: =IFERROR(__xludf.DUMMYFUNCTION("TO_PERCENT($B7/$J7)"),0.6842105263157895) | E7: =IFERROR(__xludf.DUMMYFUNCTION("IF(EQ($B7, 0), TO_PERCENT(0), TO_PERCENT($C7/$B7))"),0.5128205128205128) | F7: =COUNTIFS(MatchHistory!$B:$B, $A7, MatchHistory!$C:$C, "Mafia") | G7: =COUNTIFS(MatchHistory!$B:$B, $A7, MatchHistory!$C:$C, "Mafia", MatchHistory!$D:$D, "Win") | H7: =IFERROR(__xludf.DUMMYFUNCTION("TO_PERCENT($F7/$J7)"),0.3157894736842105) | I7: =IFERROR(__xludf.DUMMYFUNCTION("TO_PERCENT(IFERROR($G7/$F7, 0))"),0.6666666666666666) | J7: =SUM(F7, B7) | K7: =IFERROR(__xludf.DUMMYFUNCTION("TO_PERCENT(IFERROR(($G7+$C7)/($F7+$B7), 0))"),0.5614035087719298) | L7: {=INDEX(MatchHistory!$G:$G,MATCH(1,(MatchHistory!$B:$B=$A7)*(MatchHistory!$G:$G<>""),0))} | M7: {=INDEX(MatchHistory!$H:$H,MATCH(1,(MatchHistory!$B:$B=$A7)*(MatchHistory!$H:$H<>""),0))} | N7: {=INDEX(MatchHistory!$J:$J,MATCH(1,(MatchHistory!$B:$B=$A7)*(MatchHistory!$J:$J<>""),0))}
A8: Streety | B8: =COUNTIFS(MatchHistory!$B:$B, $A8, MatchHistory!$C:$C, "Town") | C8: =COUNTIFS(MatchHistory!B:B, A8, MatchHistory!C:C, "Town", MatchHistory!D:D, "Win") | D8: =IFERROR(__xludf.DUMMYFUNCTION("TO_PERCENT($B8/$J8)"),0.8148148148148148) | E8: =IFERROR(__xludf.DUMMYFUNCTION("IF(EQ($B8, 0), TO_PERCENT(0), TO_PERCENT($C8/$B8))"),0.6363636363636364) | F8: =COUNTIFS(MatchHistory!$B:$B, $A8, MatchHistory!$C:$C, "Mafia") | G8: =COUNTIFS(MatchHistory!$B:$B, $A8, MatchHistory!$C:$C, "Mafia", MatchHistory!$D:$D, "Win") | H8: =IFERROR(__xludf.DUMMYFUNCTION("TO_PERCENT($F8/$J8)"),0.18518518518518517) | I8: =IFERROR(__xludf.DUMMYFUNCTION("TO_PERCENT(IFERROR($G8/$F8, 0))"),0.6) | J8: =SUM(F8, B8) | K8: =IFERROR(__xludf.DUMMYFUNCTION("TO_PERCENT(IFERROR(($G8+$C8)/($F8+$B8), 0))"),0.6296296296296297) | L8: {=INDEX(MatchHistory!$G:$G,MATCH(1,(MatchHistory!$B:$B=$A8)*(MatchHistory!$G:$G<>""),0))} | M8: {=INDEX(MatchHistory!$H:$H,MATCH(1,(MatchHistory!$B:$B=$A8)*(MatchHistory!$H:$H<>""),0))} | N8: {=INDEX(MatchHistory!$J:$J,MATCH(1,(MatchHistory!$B:$B=$A8)*(MatchHistory!$J:$J<>""),0))}
A9: Brownkow | B9: =COUNTIFS(MatchHistory!$B:$B, $A9, MatchHistory!$C:$C, "Town") | C9: =COUNTIFS(MatchHistory!B:B, A9, MatchHistory!C:C, "Town", MatchHistory!D:D, "Win") | D9: =IFERROR(__xludf.DUMMYFUNCTION("TO_PERCENT($B9/$J9)"),0.75) | E9: =IFERROR(__xludf.DUMMYFUNCTION("IF(EQ($B9, 0), TO_PERCENT(0), TO_PERCENT($C9/$B9))"),0.5555555555555556) | F9: =COUNTIFS(MatchHistory!$B:$B, $A9, MatchHistory!$C:$C, "Mafia") | G9: =COUNTIFS(MatchHistory!$B:$B, $A9, MatchHistory!$C:$C, "Mafia", MatchHistory!$D:$D, "Win") | H9: =IFERROR(__xludf.DUMMYFUNCTION("TO_PERCENT($F9/$J9)"),0.25) | I9: =IFERROR(__xludf.DUMMYFUNCTION("TO_PERCENT(IFERROR($G9/$F9, 0))"),0.5555555555555556) | J9: =SUM(F9, B9) | K9: =IFERROR(__xludf.DUMMYFUNCTION("TO_PERCENT(IFERROR(($G9+$C9)/($F9+$B9), 0))"),0.5555555555555556) | L9: {=INDEX(MatchHistory!$G:$G,MATCH(1,(MatchHistory!$B:$B=$A9)*(MatchHistory!$G:$G<>""),0))} | M9: {=INDEX(MatchHistory!$H:$H,MATCH(1,(MatchHistory!$B:$B=$A9)*(MatchHistory!$H:$H<>""),0))} | N9: {=INDEX(MatchHistory!$J:$J,MATCH(1,(MatchHistory!$B:$B=$A9)*(MatchHistory!$J:$J<>""),0))}
A10: Iln | B10: =COUNTIFS(MatchHistory!$B:$B, $A10, MatchHistory!$C:$C, "Town") | C10: =COUNTIFS(MatchHistory!B:B, A10, MatchHistory!C:C, "Town", MatchHistory!D:D, "Win") | D10: =IFERROR(__xludf.DUMMYFUNCTION("TO_PERCENT($B10/$J10)"),0.8333333333333334) | E10: =IFERROR(__xludf.DUMMYFUNCTION("IF(EQ($B10, 0), TO_PERCENT(0), TO_PERCENT($C10/$B10))"),0.45454545454545453) | F10: =COUNTIFS(MatchHistory!$B:$B, $A10, MatchHistory!$C:$C, "Mafia") | G10: =COUNTIFS(MatchHistory!$B:$B, $A10, MatchHistory!$C:$C, "Mafia", MatchHistory!$D:$D, "Win") | H10: =IFERROR(__xludf.DUMMYFUNCTION("TO_PERCENT($F10/$J10)"),0.16666666666666666) | I10: =IFERROR(__xludf.DUMMYFUNCTION("TO_PERCENT(IFERROR($G10/$F10, 0))"),0.6363636363636364) | J10: =SUM(F10, B10) | K10: =IFERROR(__xludf.DUMMYFUNCTION("TO_PERCENT(IFERROR(($G10+$C10)/($F10+$B10), 0))"),0.48484848484848486) | L10: {=INDEX(MatchHistory!$G:$G,MATCH(1,(MatchHistory!$B:$B=$A10)*(MatchHistory!$G:$G<>""),0))} | M10: {=INDEX(MatchHistory!$H:$H,MATCH(1,(MatchHistory!$B:$B=$A10)*(MatchHistory!$H:$H<>""),0))} | N10: {=INDEX(MatchHistory!$J:$J,MATCH(1,(MatchHistory!$B:$B=$A10)*(MatchHistory!$J:$J<>""),0))}
A11: Mintt | B11: =COUNTIFS(MatchHistory!$B:$B, $A11, MatchHistory!$C:$C, "Town") | C11: =COUNTIFS(MatchHistory!B:B, A11, MatchHistory!C:C, "Town", MatchHistory!D:D, "Win") | D11: =IFERROR(__xludf.DUMMYFUNCTION("TO_PERCENT($B11/$J11)"),0.8157894736842105) | E11: =IFERROR(__xludf.DUMMYFUNCTION("IF(EQ($B11, 0), TO_PERCENT(0), TO_PERCENT($C11/$B11))"),0.5483870967741935) | F11: =COUNTIFS(MatchHistory!$B:$B, $A11, MatchHistory!$C:$C, "Mafia") | G11: =COUNTIFS(MatchHistory!$B:$B, $A11, MatchHistory!$C:$C, "Mafia", MatchHistory!$D:$D, "Win") | H11: =IFERROR(__xludf.DUMMYFUNCTION("TO_PERCENT($F11/$J11)"),0.18421052631578946) | I11: =IFERROR(__xludf.DUMMYFUNCTION("TO_PERCENT(IFERROR($G11/$F11, 0))"),0.5714285714285714) | J11: =SUM(F11, B11) | K11: =IFERROR(__xludf.DUMMYFUNCTION("TO_PERCENT(IFERROR(($G11+$C11)/($F11+$B11), 0))"),0.5526315789473685) | L11: {=INDEX(MatchHistory!$G:$G,MATCH(1,(MatchHistory!$B:$B=$A11)*(MatchHistory!$G:$G<>""),0))} | M11: {=INDEX(MatchHistory!$H:$H,MATCH(1,(MatchHistory!$B:$B=$A11)*(MatchHistory!$H:$H<>""),0))} | N11: {=INDEX(MatchHistory!$J:$J,MATCH(1,(MatchHistory!$B:$B=$A11)*(MatchHistory!$J:$J<>""),0))}
A12: Lou | B12: =COUNTIFS(MatchHistory!$B:$B, $A12, MatchHistory!$C:$C, "Town") | C12: =COUNTIFS(MatchHistory!B:B, A12, MatchHistory!C:C, "Town", MatchHistory!D:D, "Win") | D12: =IFERROR(__xludf.DUMMYFUNCTION("TO_PERCENT($B12/$J12)"),0.8275862068965517) | E12: =IFERROR(__xludf.DUMMYFUNCTION("IF(EQ($B12, 0), TO_PERCENT(0), TO_PERCENT($C12/$B12))"),0.5) | F12: =COUNTIFS(MatchHistory!$B:$B, $A12, MatchHistory!$C:$C, "Mafia") | G12: =COUNTIFS(MatchHistory!$B:$B, $A12, MatchHistory!$C:$C, "Mafia", MatchHistory!$D:$D, "Win") | H12: =IFERROR(__xludf.DUMMYFUNCTION("TO_PERCENT($F12/$J12)"),0.1724137931034483) | I12: =IFERROR(__xludf.DUMMYFUNCTION("TO_PERCENT(IFERROR($G12/$F12, 0))"),0.4) | J12: =SUM(F12, B12) | K12: =IFERROR(__xludf.DUMMYFUNCTION("TO_PERCENT(IFERROR(($G12+$C12)/($F12+$B12), 0))"),0.4827586206896552) | L12: {=INDEX(MatchHistory!$G:$G,MATCH(1,(MatchHistory!$B:$B=$A12)*(MatchHistory!$G:$G<>""),0))} | M12: {=INDEX(MatchHistory!$H:$H,MATCH(1,(MatchHistory!$B:$B=$A12)*(MatchHistory!$H:$H<>""),0))} | N12: {=INDEX(MatchHistory!$J:$J,MATCH(1,(MatchHistory!$B:$B=$A12)*(MatchHistory!$J:$J<>""),0))}
A13: Heckmuffins | B13: =COUNTIFS(MatchHistory!$B:$B, $A13, MatchHistory!$C:$C, "Town") | C13: =COUNTIFS(MatchHistory!B:B, A13, MatchHistory!C:C, "Town", MatchHistory!D:D, "Win") | D13: =IFERROR(__xludf.DUMMYFUNCTION("TO_PERCENT($B13/$J13)"),0.9) | E13: =IFERROR(__xludf.DUMMYFUNCTION("IF(EQ($B13, 0), TO_PERCENT(0), TO_PERCENT($C13/$B13))"),0.7777777777777778) | F13: =COUNTIFS(MatchHistory!$B:$B, $A13, MatchHistory!$C:$C, "Mafia") | G13: =COUNTIFS(MatchHistory!$B:$B, $A13, MatchHistory!$C:$C, "Mafia", MatchHistory!$D:$D, "Win") | H13: =IFERROR(__xludf.DUMMYFUNCTION("TO_PERCENT($F13/$J13)"),0.1) | I13: =IFERROR(__xludf.DUMMYFUNCTION("TO_PERCENT(IFERROR($G13/$F13, 0))"),1.0) | J13: =SUM(F13, B13) | K13: =IFERROR(__xludf.DUMMYFUNCTION("TO_PERCENT(IFERROR(($G13+$C13)/($F13+$B13), 0))"),0.8) | L13: {=INDEX(MatchHistory!$G:$G,MATCH(1,(MatchHistory!$B:$B=$A13)*(MatchHistory!$G:$G<>""),0))} | M13: {=INDEX(MatchHistory!$H:$H,MATCH(1,(MatchHistory!$B:$B=$A13)*(MatchHistory!$H:$H<>""),0))} | N13: {=INDEX(MatchHistory!$J:$J,MATCH(1,(MatchHistory!$B:$B=$A13)*(MatchHistory!$J:$J<>""),0))}
A14: Chester | B14: =COUNTIFS(MatchHistory!$B:$B, $A14, MatchHistory!$C:$C, "Town") | C14: =COUNTIFS(MatchHistory!B:B, A14, MatchHistory!C:C, "Town", MatchHistory!D:D, "Win") | D14: =IFERROR(__xludf.DUMMYFUNCTION("TO_PERCENT($B14/$J14)"),0.8214285714285714) | E14: =IFERROR(__xludf.DUMMYFUNCTION("IF(EQ($B14, 0), TO_PERCENT(0), TO_PERCENT($C14/$B14))"),0.5217391304347826) | F14: =COUNTIFS(MatchHistory!$B:$B, $A14, MatchHistory!$C:$C, "Mafia") | G14: =COUNTIFS(MatchHistory!$B:$B, $A14, MatchHistory!$C:$C, "Mafia", MatchHistory!$D:$D, "Win") | H14: =IFERROR(__xludf.DUMMYFUNCTION("TO_PERCENT($F14/$J14)"),0.17857142857142858) | I14: =IFERROR(__xludf.DUMMYFUNCTION("TO_PERCENT(IFERROR($G14/$F14, 0))"),0.8) | J14: =SUM(F14, B14) | K14: =IFERROR(__xludf.DUMMYFUNCTION("TO_PERCENT(IFERROR(($G14+$C14)/($F14+$B14), 0))"),0.5714285714285714) | L14: {=INDEX(MatchHistory!$G:$G,MATCH(1,(MatchHistory!$B:$B=$A14)*(MatchHistory!$G:$G<>""),0))} | M14: {=INDEX(MatchHistory!$H:$H,MATCH(1,(MatchHistory!$B:$B=$A14)*(MatchHistory!$H:$H<>""),0))} | N14: {=INDEX(MatchHistory!$J:$J,MATCH(1,(MatchHistory!$B:$B=$A14)*(MatchHistory!$J:$J<>""),0))}
A15: Josh | B15: =COUNTIFS(MatchHistory!$B:$B, $A15, MatchHistory!$C:$C, "Town") | C15: =COUNTIFS(MatchHistory!B:B, A15, MatchHistory!C:C, "Town", MatchHistory!D:D, "Win") | D15: =IFERROR(__xludf.DUMMYFUNCTION("TO_PERCENT($B15/$J15)"),0.7222222222222222) | E15: =IFERROR(__xludf.DUMMYFUNCTION("IF(EQ($B15, 0), TO_PERCENT(0), TO_PERCENT($C15/$B15))"),0.6923076923076923) | F15: =COUNTIFS(MatchHistory!$B:$B, $A15, MatchHistory!$C:$C, "Mafia") | G15: =COUNTIFS(MatchHistory!$B:$B, $A15, MatchHistory!$C:$C, "Mafia", MatchHistory!$D:$D, "Win") | H15: =IFERROR(__xludf.DUMMYFUNCTION("TO_PERCENT($F15/$J15)"),0.2777777777777778) | I15: =IFERROR(__xludf.DUMMYFUNCTION("TO_PERCENT(IFERROR($G15/$F15, 0))"),0.6) | J15: =SUM(F15, B15) | K15: =IFERROR(__xludf.DUMMYFUNCTION("TO_PERCENT(IFERROR(($G15+$C15)/($F15+$B15), 0))"),0.6666666666666666) | L15: {=INDEX(MatchHistory!$G:$G,MATCH(1,(MatchHistory!$B:$B=$A15)*(MatchHistory!$G:$G<>""),0))} | M15: {=INDEX(MatchHistory!$H:$H,MATCH(1,(MatchHistory!$B:$B=$A15)*(MatchHistory!$H:$H<>""),0))} | N15: {=INDEX(MatchHistory!$J:$J,MATCH(1,(MatchHistory!$B:$B=$A15)*(MatchHistory!$J:$J<>""),0))}
A16: Whyin | B16: =COUNTIFS(MatchHistory!$B:$B, $A16, MatchHistory!$C:$C, "Town") | C16: =COUNTIFS(MatchHistory!B:B, A16, MatchHistory!C:C, "Town", MatchHistory!D:D, "Win") | D16: =IFERROR(__xludf.DUMMYFUNCTION("TO_PERCENT($B16/$J16)"),0.75) | E16: =IFERROR(__xludf.DUMMYFUNCTION("IF(EQ($B16, 0), TO_PERCENT(0), TO_PERCENT($C16/$B16))"),0.5555555555555556) | F16: =COUNTIFS(MatchHistory!$B:$B, $A16, MatchHistory!$C:$C, "Mafia") | G16: =COUNTIFS(MatchHistory!$B:$B, $A16, MatchHistory!$C:$C, "Mafia", MatchHistory!$D:$D, "Win") | H16: =IFERROR(__xludf.DUMMYFUNCTION("TO_PERCENT($F16/$J16)"),0.25) | I16: =IFERROR(__xludf.DUMMYFUNCTION("TO_PERCENT(IFERROR($G16/$F16, 0))"),0.3333333333333333) | J16: =SUM(F16, B16) | K16: =IFERROR(__xludf.DUMMYFUNCTION("TO_PERCENT(IFERROR(($G16+$C16)/($F16+$B16), 0))"),0.5) | L16: {=INDEX(MatchHistory!$G:$G,MATCH(1,(MatchHistory!$B:$B=$A16)*(MatchHistory!$G:$G<>""),0))} | M16: {=INDEX(MatchHistory!$H:$H,MATCH(1,(MatchHistory!$B:$B=$A16)*(MatchHistory!$H:$H<>""),0))} | N16: {=INDEX(MatchHistory!$J:$J,MATCH(1,(MatchHistory!$B:$B=$A16)*(MatchHistory!$J:$J<>""),0))}
A17: Keegan | B17: =COUNTIFS(MatchHistory!$B:$B, $A17, MatchHistory!$C:$C, "Town") | C17: =COUNTIFS(MatchHistory!B:B, A17, MatchHistory!C:C, "Town", MatchHistory!D:D, "Win") | D17: =IFERROR(__xludf.DUMMYFUNCTION("TO_PERCENT($B17/$J17)"),0.8421052631578947) | E17: =IFERROR(__xludf.DUMMYFUNCTION("IF(EQ($B17, 0), TO_PERCENT(0), TO_PERCENT($C17/$B17))"),0.5625) | F17: =COUNTIFS(MatchHistory!$B:$B, $A17, MatchHistory!$C:$C, "Mafia") | G17: =COUNTIFS(MatchHistory!$B:$B, $A17, MatchHistory!$C:$C, "Mafia", MatchHistory!$D:$D, "Win") | H17: =IFERROR(__xludf.DUMMYFUNCTION("TO_PERCENT($F17/$J17)"),0.15789473684210525) | I17: =IFERROR(__xludf.DUMMYFUNCTION("TO_PERCENT(IFERROR($G17/$F17, 0))"),0.6666666666666666) | J17: =SUM(F17, B17) | K17: =IFERROR(__xludf.DUMMYFUNCTION("TO_PERCENT(IFERROR(($G17+$C17)/($F17+$B17), 0))"),0.5789473684210527) | L17: {=INDEX(MatchHistory!$G:$G,MATCH(1,(MatchHistory!$B:$B=$A17)*(MatchHistory!$G:$G<>""),0))} | M17: {=INDEX(MatchHistory!$H:$H,MATCH(1,(MatchHistory!$B:$B=$A17)*(MatchHistory!$H:$H<>""),0))} | N17: {=INDEX(MatchHistory!$J:$J,MATCH(1,(MatchHistory!$B:$B=$A17)*(MatchHistory!$J:$J<>""),0))}
A18: Strik3r | B18: =COUNTIFS(MatchHistory!$B:$B, $A18, MatchHistory!$C:$C, "Town") | C18: =COUNTIFS(MatchHistory!B:B, A18, MatchHistory!C:C, "Town", MatchHistory!D:D, "Win") | D18: =IFERROR(__xludf.DUMMYFUNCTION("TO_PERCENT($B18/$J18)"),0.75) | E18: =IFERROR(__xludf.DUMMYFUNCTION("IF(EQ($B18, 0), TO_PERCENT(0), TO_PERCENT($C18/$B18))"),0.3611111111111111) | F18: =COUNTIFS(MatchHistory!$B:$B, $A18, MatchHistory!$C:$C, "Mafia") | G18: =COUNTIFS(MatchHistory!$B:$B, $A18, MatchHistory!$C:$C, "Mafia", MatchHistory!$D:$D, "Win") | H18: =IFERROR(__xludf.DUMMYFUNCTION("TO_PERCENT($F18/$J18)"),0.25) | I18: =IFERROR(__xludf.DUMMYFUNCTION("TO_PERCENT(IFERROR($G18/$F18, 0))"),0.6666666666666666) | J18: =SUM(F18, B18) | K18: =IFERROR(__xludf.DUMMYFUNCTION("TO_PERCENT(IFERROR(($G18+$C18)/($F18+$B18), 0))"),0.4375) | L18: {=INDEX(MatchHistory!$G:$G,MATCH(1,(MatchHistory!$B:$B=$A18)*(MatchHistory!$G:$G<>""),0))} | M18: {=INDEX(MatchHistory!$H:$H,MATCH(1,(MatchHistory!$B:$B=$A18)*(MatchHistory!$H:$H<>""),0))} | N18: {=INDEX(MatchHistory!$J:$J,MATCH(1,(MatchHistory!$B:$B=$A18)*(MatchHistory!$J:$J<>""),0))}
A19: Siggy | B19: =COUNTIFS(MatchHistory!$B:$B, $A19, MatchHistory!$C:$C, "Town") | C19: =COUNTIFS(MatchHistory!B:B, A19, MatchHistory!C:C, "Town", MatchHistory!D:D, "Win") | D19: =IFERROR(__xludf.DUMMYFUNCTION("TO_PERCENT($B19/$J19)"),0.7142857142857143) | E19: =IFERROR(__xludf.DUMMYFUNCTION("IF(EQ($B19, 0), TO_PERCENT(0), TO_PERCENT($C19/$B19))"),0.7) | F19: =COUNTIFS(MatchHistory!$B:$B, $A19, MatchHistory!$C:$C, "Mafia") | G19: =COUNTIFS(MatchHistory!$B:$B, $A19, MatchHistory!$C:$C, "Mafia", MatchHistory!$D:$D, "Win") | H19: =IFERROR(__xludf.DUMMYFUNCTION("TO_PERCENT($F19/$J19)"),0.2857142857142857) | I19: =IFERROR(__xludf.DUMMYFUNCTION("TO_PERCENT(IFERROR($G19/$F19, 0))"),0.5) | J19: =SUM(F19, B19) | K19: =IFERROR(__xludf.DUMMYFUNCTION("TO_PERCENT(IFERROR(($G19+$C19)/($F19+$B19), 0))"),0.6428571428571429) | L19: {=INDEX(MatchHistory!$G:$G,MATCH(1,(MatchHistory!$B:$B=$A19)*(MatchHistory!$G:$G<>""),0))} | M19: {=INDEX(MatchHistory!$H:$H,MATCH(1,(MatchHistory!$B:$B=$A19)*(MatchHistory!$H:$H<>""),0))} | N19: {=INDEX(MatchHistory!$J:$J,MATCH(1,(MatchHistory!$B:$B=$A19)*(MatchHistory!$J:$J<>""),0))}
A20: Chipper | B20: =COUNTIFS(MatchHistory!$B:$B, $A20, MatchHistory!$C:$C, "Town") | C20: =COUNTIFS(MatchHistory!B:B, A20, MatchHistory!C:C, "Town", MatchHistory!D:D, "Win") | D20: =IFERROR(__xludf.DUMMYFUNCTION("TO_PERCENT($B20/$J20)"),0.7727272727272727) | E20: =IFERROR(__xludf.DUMMYFUNCTION("IF(EQ($B20, 0), TO_PERCENT(0), TO_PERCENT($C20/$B20))"),0.4117647058823529) | F20: =COUNTIFS(MatchHistory!$B:$B, $A20, MatchHistory!$C:$C, "Mafia") | G20: =COUNTIFS(MatchHistory!$B:$B, $A20, MatchHistory!$C:$C, "Mafia", MatchHistory!$D:$D, "Win") | H20: =IFERROR(__xludf.DUMMYFUNCTION("TO_PERCENT($F20/$J20)"),0.22727272727272727) | I20: =IFERROR(__xludf.DUMMYFUNCTION("TO_PERCENT(IFERROR($G20/$F20, 0))"),0.5) | J20: =SUM(F20, B20) | K20: =IFERROR(__xludf.DUMMYFUNCTION("TO_PERCENT(IFERROR(($G20+$C20)/($F20+$B20), 0))"),0.4318181818181818) | L20: {=INDEX(MatchHistory!$G:$G,MATCH(1,(MatchHistory!$B:$B=$A20)*(MatchHistory!$G:$G<>""),0))} | M20: {=INDEX(MatchHistory!$H:$H,MATCH(1,(MatchHistory!$B:$B=$A20)*(MatchHistory!$H:$H<>""),0))} | N20: {=INDEX(MatchHistory!$J:$J,MATCH(1,(MatchHistory!$B:$B=$A20)*(MatchHistory!$J:$J<>""),0))}
A21: Carson | B21: =COUNTIFS(MatchHistory!$B:$B, $A21, MatchHistory!$C:$C, "Town") | C21: =COUNTIFS(MatchHistory!B:B, A21, MatchHistory!C:C, "Town", MatchHistory!D:D, "Win") | D21: =IFERROR(__xludf.DUMMYFUNCTION("TO_PERCENT($B21/$J21)"),0.8333333333333334) | E21: =IFERROR(__xludf.DUMMYFUNCTION("IF(EQ($B21, 0), TO_PERCENT(0), TO_PERCENT($C21/$B21))"),0.4888888888888889) | F21: =COUNTIFS(MatchHistory!$B:$B, $A21, MatchHistory!$C:$C, "Mafia") | G21: =COUNTIFS(MatchHistory!$B:$B, $A21, MatchHistory!$C:$C, "Mafia", MatchHistory!$D:$D, "Win") | H21: =IFERROR(__xludf.DUMMYFUNCTION("TO_PERCENT($F21/$J21)"),0.16666666666666666) | I21: =IFERROR(__xludf.DUMMYFUNCTION("TO_PERCENT(IFERROR($G21/$F21, 0))"),0.3333333333333333) | J21: =SUM(F21, B21) | K21: =IFERROR(__xludf.DUMMYFUNCTION("TO_PERCENT(IFERROR(($G21+$C21)/($F21+$B21), 0))"),0.46296296296296297) | L21: {=INDEX(MatchHistory!$G:$G,MATCH(1,(MatchHistory!$B:$B=$A21)*(MatchHistory!$G:$G<>""),0))} | M21: {=INDEX(MatchHistory!$H:$H,MATCH(1,(MatchHistory!$B:$B=$A21)*(MatchHistory!$H:$H<>""),0))} | N21: {=INDEX(MatchHistory!$J:$J,MATCH(1,(MatchHistory!$B:$B=$A21)*(MatchHistory!$J:$J<>""),0))}
A22: Xcync | B22: =COUNTIFS(MatchHistory!$B:$B, $A22, MatchHistory!$C:$C, "Town") | C22: =COUNTIFS(MatchHistory!B:B, A22, MatchHistory!C:C, "Town", MatchHistory!D:D, "Win") | D22: =IFERROR(__xludf.DUMMYFUNCTION("TO_PERCENT($B22/$J22)"),0.7142857142857143) | E22: =IFERROR(__xludf.DUMMYFUNCTION("IF(EQ($B22, 0), TO_PERCENT(0), TO_PERCENT($C22/$B22))"),0.7) | F22: =COUNTIFS(MatchHistory!$B:$B, $A22, MatchHistory!$C:$C, "Mafia") | G22: =COUNTIFS(MatchHistory!$B:$B, $A22, MatchHistory!$C:$C, "Mafia", MatchHistory!$D:$D, "Win") | H22: =IFERROR(__xludf.DUMMYFUNCTION("TO_PERCENT($F22/$J22)"),0.2857142857142857) | I22: =IFERROR(__xludf.DUMMYFUNCTION("TO_PERCENT(IFERROR($G22/$F22, 0))"),0.5) | J22: =SUM(F22, B22) | K22: =IFERROR(__xludf.DUMMYFUNCTION("TO_PERCENT(IFERROR(($G22+$C22)/($F22+$B22), 0))"),0.6428571428571429) | L22: {=INDEX(MatchHistory!$G:$G,MATCH(1,(MatchHistory!$B:$B=$A22)*(MatchHistory!$G:$G<>""),0))} | M22: {=INDEX(MatchHistory!$H:$H,MATCH(1,(MatchHistory!$B:$B=$A22)*(MatchHistory!$H:$H<>""),0))} | N22: {=INDEX(MatchHistory!$J:$J,MATCH(1,(MatchHistory!$B:$B=$A22)*(MatchHistory!$J:$J<>""),0))}
A23: Cj | B23: =COUNTIFS(MatchHistory!$B:$B, $A23, MatchHistory!$C:$C, "Town") | C23: =COUNTIFS(MatchHistory!B:B, A23, MatchHistory!C:C, "Town", MatchHistory!D:D, "Win") | D23: =IFERROR(__xludf.DUMMYFUNCTION("TO_PERCENT($B23/$J23)"),0.8333333333333334) | E23: =IFERROR(__xludf.DUMMYFUNCTION("IF(EQ($B23, 0), TO_PERCENT(0), TO_PERCENT($C23/$B23))"),0.5333333333333333) | F23: =COUNTIFS(MatchHistory!$B:$B, $A23, MatchHistory!$C:$C, "Mafia") | G23: =COUNTIFS(MatchHistory!$B:$B, $A23, MatchHistory!$C:$C, "Mafia", MatchHistory!$D:$D, "Win") | H23: =IFERROR(__xludf.DUMMYFUNCTION("TO_PERCENT($F23/$J23)"),0.16666666666666666) | I23: =IFERROR(__xludf.DUMMYFUNCTION("TO_PERCENT(IFERROR($G23/$F23, 0))"),0.3333333333333333) | J23: =SUM(F23, B23) | K23: =IFERROR(__xludf.DUMMYFUNCTION("TO_PERCENT(IFERROR(($G23+$C23)/($F23+$B23), 0))"),0.5) | L23: {=INDEX(MatchHistory!$G:$G,MATCH(1,(MatchHistory!$B:$B=$A23)*(MatchHistory!$G:$G<>""),0))} | M23: {=INDEX(MatchHistory!$H:$H,MATCH(1,(MatchHistory!$B:$B=$A23)*(MatchHistory!$H:$H<>""),0))} | N23: {=INDEX(MatchHistory!$J:$J,MATCH(1,(MatchHistory!$B:$B=$A23)*(MatchHistory!$J:$J<>""),0))}
A24: Svaan | B24: =COUNTIFS(MatchHistory!$B:$B, $A24, MatchHistory!$C:$C, "Town") | C24: =COUNTIFS(MatchHistory!B:B, A24, MatchHistory!C:C, "Town", MatchHistory!D:D, "Win") | D24: =IFERROR(__xludf.DUMMYFUNCTION("TO_PERCENT($B24/$J24)"),0.7368421052631579) | E24: =IFERROR(__xludf.DUMMYFUNCTION("IF(EQ($B24, 0), TO_PERCENT(0), TO_PERCENT($C24/$B24))"),0.5714285714285714) | F24: =COUNTIFS(MatchHistory!$B:$B, $A24, MatchHistory!$C:$C, "Mafia") | G24: =COUNTIFS(MatchHistory!$B:$B, $A24, MatchHistory!$C:$C, "Mafia", MatchHistory!$D:$D, "Win") | H24: =IFERROR(__xludf.DUMMYFUNCTION("TO_PERCENT($F24/$J24)"),0.2631578947368421) | I24: =IFERROR(__xludf.DUMMYFUNCTION("TO_PERCENT(IFERROR($G24/$F24, 0))"),0.6) | J24: =SUM(F24, B24) | K24: =IFERROR(__xludf.DUMMYFUNCTION("TO_PERCENT(IFERROR(($G24+$C24)/($F24+$B24), 0))"),0.5789473684210527) | L24: {=INDEX(MatchHistory!$G:$G,MATCH(1,(MatchHistory!$B:$B=$A24)*(MatchHistory!$G:$G<>""),0))} | M24: {=INDEX(MatchHistory!$H:$H,MATCH(1,(MatchHistory!$B:$B=$A24)*(MatchHistory!$H:$H<>""),0))} | N24: {=INDEX(MatchHistory!$J:$J,MATCH(1,(MatchHistory!$B:$B=$A24)*(MatchHistory!$J:$J<>""),0))}
A25: Rick | B25: =COUNTIFS(MatchHistory!$B:$B, $A25, MatchHistory!$C:$C, "Town") | C25: =COUNTIFS(MatchHistory!B:B, A25, MatchHistory!C:C, "Town", MatchHistory!D:D, "Win") | D25: =IFERROR(__xludf.DUMMYFUNCTION("TO_PERCENT($B25/$J25)"),0.6875) | E25: =IFERROR(__xludf.DUMMYFUNCTION("IF(EQ($B25, 0), TO_PERCENT(0), TO_PERCENT($C25/$B25))"),0.45454545454545453) | F25: =COUNTIFS(MatchHistory!$B:$B, $A25, MatchHistory!$C:$C, "Mafia") | G25: =COUNTIFS(MatchHistory!$B:$B, $A25, MatchHistory!$C:$C, "Mafia", MatchHistory!$D:$D, "Win") | H25: =IFERROR(__xludf.DUMMYFUNCTION("TO_PERCENT($F25/$J25)"),0.3125) | I25: =IFERROR(__xludf.DUMMYFUNCTION("TO_PERCENT(IFERROR($G25/$F25, 0))"),1.0) | J25: =SUM(F25, B25) | K25: =IFERROR(__xludf.DUMMYFUNCTION("TO_PERCENT(IFERROR(($G25+$C25)/($F25+$B25), 0))"),0.625) | L25: {=INDEX(MatchHistory!$G:$G,MATCH(1,(MatchHistory!$B:$B=$A25)*(MatchHistory!$G:$G<>""),0))} | M25: {=INDEX(MatchHistory!$H:$H,MATCH(1,(MatchHistory!$B:$B=$A25)*(MatchHistory!$H:$H<>""),0))} | N25: {=INDEX(MatchHistory!$J:$J,MATCH(1,(MatchHistory!$B:$B=$A25)*(MatchHistory!$J:$J<>""),0))}
A26: Chelsea | B26: =COUNTIFS(MatchHistory!$B:$B, $A26, MatchHistory!$C:$C, "Town") | C26: =COUNTIFS(MatchHistory!B:B, A26, MatchHistory!C:C, "Town", MatchHistory!D:D, "Win") | D26: =IFERROR(__xludf.DUMMYFUNCTION("TO_PERCENT($B26/$J26)"),0.8181818181818182) | E26: =IFERROR(__xludf.DUMMYFUNCTION("IF(EQ($B26, 0), TO_PERCENT(0), TO_PERCENT($C26/$B26))"),0.6111111111111112) | F26: =COUNTIFS(MatchHistory!$B:$B, $A26, MatchHistory!$C:$C, "Mafia") | G26: =COUNTIFS(MatchHistory!$B:$B, $A26, MatchHistory!$C:$C, "Mafia", MatchHistory!$D:$D, "Win") | H26: =IFERROR(__xludf.DUMMYFUNCTION("TO_PERCENT($F26/$J26)"),0.18181818181818182) | I26: =IFERROR(__xludf.DUMMYFUNCTION("TO_PERCENT(IFERROR($G26/$F26, 0))"),0.0) | J26: =SUM(F26, B26) | K26: =IFERROR(__xludf.DUMMYFUNCTION("TO_PERCENT(IFERROR(($G26+$C26)/($F26+$B26), 0))"),0.5) | L26: {=INDEX(MatchHistory!$G:$G,MATCH(1,(MatchHistory!$B:$B=$A26)*(MatchHistory!$G:$G<>""),0))} | M26: {=INDEX(MatchHistory!$H:$H,MATCH(1,(MatchHistory!$B:$B=$A26)*(MatchHistory!$H:$H<>""),0))} | N26: {=INDEX(MatchHistory!$J:$J,MATCH(1,(MatchHistory!$B:$B=$A26)*(MatchHistory!$J:$J<>""),0))}
A27: Kden | B27: =COUNTIFS(MatchHistory!$B:$B, $A27, MatchHistory!$C:$C, "Town") | C27: =COUNTIFS(MatchHistory!B:B, A27, MatchHistory!C:C, "Town", MatchHistory!D:D, "Win") | D27: =IFERROR(__xludf.DUMMYFUNCTION("TO_PERCENT($B27/$J27)"),0.8085106382978723) | E27: =IFERROR(__xludf.DUMMYFUNCTION("IF(EQ($B27, 0), TO_PERCENT(0), TO_PERCENT($C27/$B27))"),0.39473684210526316) | F27: =COUNTIFS(MatchHistory!$B:$B, $A27, MatchHistory!$C:$C, "Mafia") | G27: =COUNTIFS(MatchHistory!$B:$B, $A27, MatchHistory!$C:$C, "Mafia", MatchHistory!$D:$D, "Win") | H27: =IFERROR(__xludf.DUMMYFUNCTION("TO_PERCENT($F27/$J27)"),0.19148936170212766) | I27: =IFERROR(__xludf.DUMMYFUNCTION("TO_PERCENT(IFERROR($G27/$F27, 0))"),0.4444444444444444) | J27: =SUM(F27, B27) | K27: =IFERROR(__xludf.DUMMYFUNCTION("TO_PERCENT(IFERROR(($G27+$C27)/($F27+$B27), 0))"),0.40425531914893614) | L27: {=INDEX(MatchHistory!$G:$G,MATCH(1,(MatchHistory!$B:$B=$A27)*(MatchHistory!$G:$G<>""),0))} | M27: {=INDEX(MatchHistory!$H:$H,MATCH(1,(MatchHistory!$B:$B=$A27)*(MatchHistory!$H:$H<>""),0))} | N27: {=INDEX(MatchHistory!$J:$J,MATCH(1,(MatchHistory!$B:$B=$A27)*(MatchHistory!$J:$J<>""),0))}
A28: Gilbert | B28: =COUNTIFS(MatchHistory!$B:$B, $A28, MatchHistory!$C:$C, "Town") | C28: =COUNTIFS(MatchHistory!B:B, A28, MatchHistory!C:C, "Town", MatchHistory!D:D, "Win") | D28: =IFERROR(__xludf.DUMMYFUNCTION("TO_PERCENT($B28/$J28)"),0.7894736842105263) | E28: =IFERROR(__xludf.DUMMYFUNCTION("IF(EQ($B28, 0), TO_PERCENT(0), TO_PERCENT($C28/$B28))"),0.5) | F28: =COUNTIFS(MatchHistory!$B:$B, $A28, MatchHistory!$C:$C, "Mafia") | G28: =COUNTIFS(MatchHistory!$B:$B, $A28, MatchHistory!$C:$C, "Mafia", MatchHistory!$D:$D, "Win") | H28: =IFERROR(__xludf.DUMMYFUNCTION("TO_PERCENT($F28/$J28)"),0.21052631578947367) | I28: =IFERROR(__xludf.DUMMYFUNCTION("TO_PERCENT(IFERROR($G28/$F28, 0))"),0.375) | J28: =SUM(F28, B28) | K28: =IFERROR(__xludf.DUMMYFUNCTION("TO_PERCENT(IFERROR(($G28+$C28)/($F28+$B28), 0))"),0.47368421052631576) | L28: {=INDEX(MatchHistory!$G:$G,MATCH(1,(MatchHistory!$B:$B=$A28)*(MatchHistory!$G:$G<>""),0))} | M28: {=INDEX(MatchHistory!$H:$H,MATCH(1,(MatchHistory!$B:$B=$A28)*(MatchHistory!$H:$H<>""),0))} | N28: {=INDEX(MatchHistory!$J:$J,MATCH(1,(MatchHistory!$B:$B=$A28)*(MatchHistory!$J:$J<>""),0))}
A29: Lofty | B29: =COUNTIFS(MatchHistory!$B:$B, $A29, MatchHistory!$C:$C, "Town") | C29: =COUNTIFS(MatchHistory!B:B, A29, MatchHistory!C:C, "Town", MatchHistory!D:D, "Win") | D29: =IFERROR(__xludf.DUMMYFUNCTION("TO_PERCENT($B29/$J29)"),0.7142857142857143) | E29: =IFERROR(__xludf.DUMMYFUNCTION("IF(EQ($B29, 0), TO_PERCENT(0), TO_PERCENT($C29/$B29))"),0.3) | F29: =COUNTIFS(MatchHistory!$B:$B, $A29, MatchHistory!$C:$C, "Mafia") | G29: =COUNTIFS(MatchHistory!$B:$B, $A29, MatchHistory!$C:$C, "Mafia", MatchHistory!$D:$D, "Win") | H29: =IFERROR(__xludf.DUMMYFUNCTION("TO_PERCENT($F29/$J29)"),0.2857142857142857) | I29: =IFERROR(__xludf.DUMMYFUNCTION("TO_PERCENT(IFERROR($G29/$F29, 0))"),1.0) | J29: =SUM(F29, B29) | K29: =IFERROR(__xludf.DUMMYFUNCTION("TO_PERCENT(IFERROR(($G29+$C29)/($F29+$B29), 0))"),0.5) | L29: {=INDEX(MatchHistory!$G:$G,MATCH(1,(MatchHistory!$B:$B=$A29)*(MatchHistory!$G:$G<>""),0))} | M29: {=INDEX(MatchHistory!$H:$H,MATCH(1,(MatchHistory!$B:$B=$A29)*(MatchHistory!$H:$H<>""),0))} | N29: {=INDEX(MatchHistory!$J:$J,MATCH(1,(MatchHistory!$B:$B=$A29)*(MatchHistory!$J:$J<>""),0))}
A30: Motr | B30: =COUNTIFS(MatchHistory!$B:$B, $A30, MatchHistory!$C:$C, "Town") | C30: =COUNTIFS(MatchHistory!B:B, A30, MatchHistory!C:C, "Town", MatchHistory!D:D, "Win") | D30: =IFERROR(__xludf.DUMMYFUNCTION("TO_PERCENT($B30/$J30)"),0.6071428571428571) | E30: =IFERROR(__xludf.DUMMYFUNCTION("IF(EQ($B30, 0), TO_PERCENT(0), TO_PERCENT($C30/$B30))"),0.5882352941176471) | F30: =COUNTIFS(MatchHistory!$B:$B, $A30, MatchHistory!$C:$C, "Mafia") | G30: =COUNTIFS(MatchHistory!$B:$B, $A30, MatchHistory!$C:$C, "Mafia", MatchHistory!$D:$D, "Win") | H30: =IFERROR(__xludf.DUMMYFUNCTION("TO_PERCENT($F30/$J30)"),0.39285714285714285) | I30: =IFERROR(__xludf.DUMMYFUNCTION("TO_PERCENT(IFERROR($G30/$F30, 0))"),0.36363636363636365) | J30: =SUM(F30, B30) | K30: =IFERROR(__xludf.DUMMYFUNCTION("TO_PERCENT(IFERROR(($G30+$C30)/($F30+$B30), 0))"),0.5) | L30: {=INDEX(MatchHistory!$G:$G,MATCH(1,(MatchHistory!$B:$B=$A30)*(MatchHistory!$G:$G<>""),0))} | M30: {=INDEX(MatchHistory!$H:$H,MATCH(1,(MatchHistory!$B:$B=$A30)*(MatchHistory!$H:$H<>""),0))} | N30: {=INDEX(MatchHistory!$J:$J,MATCH(1,(MatchHistory!$B:$B=$A30)*(MatchHistory!$J:$J<>""),0))}
A31: Cody | B31: =COUNTIFS(MatchHistory!$B:$B, $A31, MatchHistory!$C:$C, "Town") | C31: =COUNTIFS(MatchHistory!B:B, A31, MatchHistory!C:C, "Town", MatchHistory!D:D, "Win") | D31: =IFERROR(__xludf.DUMMYFUNCTION("TO_PERCENT($B31/$J31)"),1.0) | E31: =IFERROR(__xludf.DUMMYFUNCTION("IF(EQ($B31, 0), TO_PERCENT(0), TO_PERCENT($C31/$B31))"),1.0) | F31: =COUNTIFS(MatchHistory!$B:$B, $A31, MatchHistory!$C:$C, "Mafia") | G31: =COUNTIFS(MatchHistory!$B:$B, $A31, MatchHistory!$C:$C, "Mafia", MatchHistory!$D:$D, "Win") | H31: =IFERROR(__xludf.DUMMYFUNCTION("TO_PERCENT($F31/$J31)"),0.0) | I31: =IFERROR(__xludf.DUMMYFUNCTION("TO_PERCENT(IFERROR($G31/$F31, 0))"),0.0) | J31: =SUM(F31, B31) | K31: =IFERROR(__xludf.DUMMYFUNCTION("TO_PERCENT(IFERROR(($G31+$C31)/($F31+$B31), 0))"),1.0) | L31: {=INDEX(MatchHistory!$G:$G,MATCH(1,(MatchHistory!$B:$B=$A31)*(MatchHistory!$G:$G<>""),0))} | M31: {=INDEX(MatchHistory!$H:$H,MATCH(1,(MatchHistory!$B:$B=$A31)*(MatchHistory!$H:$H<>""),0))} | N31: {=INDEX(MatchHistory!$J:$J,MATCH(1,(MatchHistory!$B:$B=$A31)*(MatchHistory!$J:$J<>""),0))}
A32: Badpants | B32: =COUNTIFS(MatchHistory!$B:$B, $A32, MatchHistory!$C:$C, "Town") | C32: =COUNTIFS(MatchHistory!B:B, A32, MatchHistory!C:C, "Town", MatchHistory!D:D, "Win") | D32: =IFERROR(__xludf.DUMMYFUNCTION("TO_PERCENT($B32/$J32)"),0.7368421052631579) | E32: =IFERROR(__xludf.DUMMYFUNCTION("IF(EQ($B32, 0), TO_PERCENT(0), TO_PERCENT($C32/$B32))"),0.40476190476190477) | F32: =COUNTIFS(MatchHistory!$B:$B, $A32, MatchHistory!$C:$C, "Mafia") | G32: =COUNTIFS(MatchHistory!$B:$B, $A32, MatchHistory!$C:$C, "Mafia", MatchHistory!$D:$D, "Win") | H32: =IFERROR(__xludf.DUMMYFUNCTION("TO_PERCENT($F32/$J32)"),0.2631578947368421) | I32: =IFERROR(__xludf.DUMMYFUNCTION("TO_PERCENT(IFERROR($G32/$F32, 0))"),0.4666666666666667) | J32: =SUM(F32, B32) | K32: =IFERROR(__xludf.DUMMYFUNCTION("TO_PERCENT(IFERROR(($G32+$C32)/($F32+$B32), 0))"),0.42105263157894735) | L32: {=INDEX(MatchHistory!$G:$G,MATCH(1,(MatchHistory!$B:$B=$A32)*(MatchHistory!$G:$G<>""),0))} | M32: {=INDEX(MatchHistory!$H:$H,MATCH(1,(MatchHistory!$B:$B=$A32)*(MatchHistory!$H:$H<>""),0))} | N32: {=INDEX(MatchHistory!$J:$J,MATCH(1,(MatchHistory!$B:$B=$A32)*(MatchHistory!$J:$J<>""),0))}
A33: Starv | B33: =COUNTIFS(MatchHistory!$B:$B, $A33, MatchHistory!$C:$C, "Town") | C33: =COUNTIFS(MatchHistory!B:B, A33, MatchHistory!C:C, "Town", MatchHistory!D:D, "Win") | D33: =IFERROR(__xludf.DUMMYFUNCTION("TO_PERCENT($B33/$J33)"),0.8) | E33: =IFERROR(__xludf.DUMMYFUNCTION("IF(EQ($B33, 0), TO_PERCENT(0), TO_PERCENT($C33/$B33))"),0.75) | F33: =COUNTIFS(MatchHistory!$B:$B, $A33, MatchHistory!$C:$C, "Mafia") | G33: =COUNTIFS(MatchHistory!$B:$B, $A33, MatchHistory!$C:$C, "Mafia", MatchHistory!$D:$D, "Win") | H33: =IFERROR(__xludf.DUMMYFUNCTION("TO_PERCENT($F33/$J33)"),0.2) | I33: =IFERROR(__xludf.DUMMYFUNCTION("TO_PERCENT(IFERROR($G33/$F33, 0))"),1.0) | J33: =SUM(F33, B33) | K33: =IFERROR(__xludf.DUMMYFUNCTION("TO_PERCENT(IFERROR(($G33+$C33)/($F33+$B33), 0))"),0.8) | L33: {=INDEX(MatchHistory!$G:$G,MATCH(1,(MatchHistory!$B:$B=$A33)*(MatchHistory!$G:$G<>""),0))} | M33: {=INDEX(MatchHistory!$H:$H,MATCH(1,(MatchHistory!$B:$B=$A33)*(MatchHistory!$H:$H<>""),0))} | N33: {=INDEX(MatchHistory!$J:$J,MATCH(1,(MatchHistory!$B:$B=$A33)*(MatchHistory!$J:$J<>""),0))}
A34: Crispy | B34: =COUNTIFS(MatchHistory!$B:$B, $A34, MatchHistory!$C:$C, "Town") | C34: =COUNTIFS(MatchHistory!B:B, A34, MatchHistory!C:C, "Town", MatchHistory!D:D, "Win") | D34: =IFERROR(__xludf.DUMMYFUNCTION("TO_PERCENT($B34/$J34)"),0.75) | E34: =IFERROR(__xludf.DUMMYFUNCTION("IF(EQ($B34, 0), TO_PERCENT(0), TO_PERCENT($C34/$B34))"),0.6666666666666666) | F34: =COUNTIFS(MatchHistory!$B:$B, $A34, MatchHistory!$C:$C, "Mafia") | G34: =COUNTIFS(MatchHistory!$B:$B, $A34, MatchHistory!$C:$C, "Mafia", MatchHistory!$D:$D, "Win") | H34: =IFERROR(__xludf.DUMMYFUNCTION("TO_PERCENT($F34/$J34)"),0.25) | I34: =IFERROR(__xludf.DUMMYFUNCTION("TO_PERCENT(IFERROR($G34/$F34, 0))"),1.0) | J34: =SUM(F34, B34) | K34: =IFERROR(__xludf.DUMMYFUNCTION("TO_PERCENT(IFERROR(($G34+$C34)/($F34+$B34), 0))"),0.75) | L34: {=INDEX(MatchHistory!$G:$G,MATCH(1,(MatchHistory!$B:$B=$A34)*(MatchHistory!$G:$G<>""),0))} | M34: {=INDEX(MatchHistory!$H:$H,MATCH(1,(MatchHistory!$B:$B=$A34)*(MatchHistory!$H:$H<>""),0))} | N34: {=INDEX(MatchHistory!$J:$J,MATCH(1,(MatchHistory!$B:$B=$A34)*(MatchHistory!$J:$J<>""),0))}
A35: Pinkee | B35: =COUNTIFS(MatchHistory!$B:$B, $A35, MatchHistory!$C:$C, "Town") | C35: =COUNTIFS(MatchHistory!B:B, A35, MatchHistory!C:C, "Town", MatchHistory!D:D, "Win") | D35: =IFERROR(__xludf.DUMMYFUNCTION("TO_PERCENT($B35/$J35)"),1.0) | E35: =IFERROR(__xludf.DUMMYFUNCTION("IF(EQ($B35, 0), TO_PERCENT(0), TO_PERCENT($C35/$B35))"),0.75) | F35: =COUNTIFS(MatchHistory!$B:$B, $A35, MatchHistory!$C:$C, "Mafia") | G35: =COUNTIFS(MatchHistory!$B:$B, $A35, MatchHistory!$C:$C, "Mafia", MatchHistory!$D:$D, "Win") | H35: =IFERROR(__xludf.DUMMYFUNCTION("TO_PERCENT($F35/$J35)"),0.0) | I35: =IFERROR(__xludf.DUMMYFUNCTION("TO_PERCENT(IFERROR($G35/$F35, 0))"),0.0) | J35: =SUM(F35, B35) | K35: =IFERROR(__xludf.DUMMYFUNCTION("TO_PERCENT(IFERROR(($G35+$C35)/($F35+$B35), 0))"),0.75) | L35: {=INDEX(MatchHistory!$G:$G,MATCH(1,(MatchHistory!$B:$B=$A35)*(MatchHistory!$G:$G<>""),0))} | M35: {=INDEX(MatchHistory!$H:$H,MATCH(1,(MatchHistory!$B:$B=$A35)*(MatchHistory!$H:$H<>""),0))} | N35: {=INDEX(MatchHistory!$J:$J,MATCH(1,(MatchHistory!$B:$B=$A35)*(MatchHistory!$J:$J<>""),0))}
A36: Boobles | B36: =COUNTIFS(MatchHistory!$B:$B, $A36, MatchHistory!$C:$C, "Town") | C36: =COUNTIFS(MatchHistory!B:B, A36, MatchHistory!C:C, "Town", MatchHistory!D:D, "Win") | D36: =IFERROR(__xludf.DUMMYFUNCTION("TO_PERCENT($B36/$J36)"),0.75) | E36: =IFERROR(__xludf.DUMMYFUNCTION("IF(EQ($B36, 0), TO_PERCENT(0), TO_PERCENT($C36/$B36))"),0.6666666666666666) | F36: =COUNTIFS(MatchHistory!$B:$B, $A36, MatchHistory!$C:$C, "Mafia") | G36: =COUNTIFS(MatchHistory!$B:$B, $A36, MatchHistory!$C:$C, "Mafia", MatchHistory!$D:$D, "Win") | H36: =IFERROR(__xludf.DUMMYFUNCTION("TO_PERCENT($F36/$J36)"),0.25) | I36: =IFERROR(__xludf.DUMMYFUNCTION("TO_PERCENT(IFERROR($G36/$F36, 0))"),0.5) | J36: =SUM(F36, B36) | K36: =IFERROR(__xludf.DUMMYFUNCTION("TO_PERCENT(IFERROR(($G36+$C36)/($F36+$B36), 0))"),0.625) | L36: {=INDEX(MatchHistory!$G:$G,MATCH(1,(MatchHistory!$B:$B=$A36)*(MatchHistory!$G:$G<>""),0))} | M36: {=INDEX(MatchHistory!$H:$H,MATCH(1,(MatchHistory!$B:$B=$A36)*(MatchHistory!$H:$H<>""),0))} | N36: {=INDEX(MatchHistory!$J:$J,MATCH(1,(MatchHistory!$B:$B=$A36)*(MatchHistory!$J:$J<>""),0))}
A37: Jake | B37: =COUNTIFS(MatchHistory!$B:$B, $A37, MatchHistory!$C:$C, "Town") | C37: =COUNTIFS(MatchHistory!B:B, A37, MatchHistory!C:C, "Town", MatchHistory!D:D, "Win") | D37: =IFERROR(__xludf.DUMMYFUNCTION("TO_PERCENT($B37/$J37)"),1.0) | E37: =IFERROR(__xludf.DUMMYFUNCTION("IF(EQ($B37, 0), TO_PERCENT(0), TO_PERCENT($C37/$B37))"),0.6666666666666666) | F37: =COUNTIFS(MatchHistory!$B:$B, $A37, MatchHistory!$C:$C, "Mafia") | G37: =COUNTIFS(MatchHistory!$B:$B, $A37, MatchHistory!$C:$C, "Mafia", MatchHistory!$D:$D, "Win") | H37: =IFERROR(__xludf.DUMMYFUNCTION("TO_PERCENT($F37/$J37)"),0.0) | I37: =IFERROR(__xludf.DUMMYFUNCTION("TO_PERCENT(IFERROR($G37/$F37, 0))"),0.0) | J37: =SUM(F37, B37) | K37: =IFERROR(__xludf.DUMMYFUNCTION("TO_PERCENT(IFERROR(($G37+$C37)/($F37+$B37), 0))"),0.6666666666666666) | L37: {=INDEX(MatchHistory!$G:$G,MATCH(1,(MatchHistory!$B:$B=$A37)*(MatchHistory!$G:$G<>""),0))} | M37: {=INDEX(MatchHistory!$H:$H,MATCH(1,(MatchHistory!$B:$B=$A37)*(MatchHistory!$H:$H<>""),0))} | N37: {=INDEX(MatchHistory!$J:$J,MATCH(1,(MatchHistory!$B:$B=$A37)*(MatchHistory!$J:$J<>""),0))}
A38: Snazz | B38: =COUNTIFS(MatchHistory!$B:$B, $A38, MatchHistory!$C:$C, "Town") | C38: =COUNTIFS(MatchHistory!B:B, A38, MatchHistory!C:C, "Town", MatchHistory!D:D, "Win") | D38: =IFERROR(__xludf.DUMMYFUNCTION("TO_PERCENT($B38/$J38)"),0.7) | E38: =IFERROR(__xludf.DUMMYFUNCTION("IF(EQ($B38, 0), TO_PERCENT(0), TO_PERCENT($C38/$B38))"),0.2857142857142857) | F38: =COUNTIFS(MatchHistory!$B:$B, $A38, MatchHistory!$C:$C, "Mafia") | G38: =COUNTIFS(MatchHistory!$B:$B, $A38, MatchHistory!$C:$C, "Mafia", MatchHistory!$D:$D, "Win") | H38: =IFERROR(__xludf.DUMMYFUNCTION("TO_PERCENT($F38/$J38)"),0.3) | I38: =IFERROR(__xludf.DUMMYFUNCTION("TO_PERCENT(IFERROR($G38/$F38, 0))"),1.0) | J38: =SUM(F38, B38) | K38: =IFERROR(__xludf.DUMMYFUNCTION("TO_PERCENT(IFERROR(($G38+$C38)/($F38+$B38), 0))"),0.5) | L38: {=INDEX(MatchHistory!$G:$G,MATCH(1,(MatchHistory!$B:$B=$A38)*(MatchHistory!$G:$G<>""),0))} | M38: {=INDEX(MatchHistory!$H:$H,MATCH(1,(MatchHistory!$B:$B=$A38)*(MatchHistory!$H:$H<>""),0))} | N38: {=INDEX(MatchHistory!$J:$J,MATCH(1,(MatchHistory!$B:$B=$A38)*(MatchHistory!$J:$J<>""),0))}
A39: Qe | B39: =COUNTIFS(MatchHistory!$B:$B, $A39, MatchHistory!$C:$C, "Town") | C39: =COUNTIFS(MatchHistory!B:B, A39, MatchHistory!C:C, "Town", MatchHistory!D:D, "Win") | D39: =IFERROR(__xludf.DUMMYFUNCTION("TO_PERCENT($B39/$J39)"),1.0) | E39: =IFERROR(__xludf.DUMMYFUNCTION("IF(EQ($B39, 0), TO_PERCENT(0), TO_PERCENT($C39/$B39))"),1.0) | F39: =COUNTIFS(MatchHistory!$B:$B, $A39, MatchHistory!$C:$C, "Mafia") | G39: =COUNTIFS(MatchHistory!$B:$B, $A39, MatchHistory!$C:$C, "Mafia", MatchHistory!$D:$D, "Win") | H39: =IFERROR(__xludf.DUMMYFUNCTION("TO_PERCENT($F39/$J39)"),0.0) | I39: =IFERROR(__xludf.DUMMYFUNCTION("TO_PERCENT(IFERROR($G39/$F39, 0))"),0.0) | J39: =SUM(F39, B39) | K39: =IFERROR(__xludf.DUMMYFUNCTION("TO_PERCENT(IFERROR(($G39+$C39)/($F39+$B39), 0))"),1.0) | L39: {=INDEX(MatchHistory!$G:$G,MATCH(1,(MatchHistory!$B:$B=$A39)*(MatchHistory!$G:$G<>""),0))} | M39: {=INDEX(MatchHistory!$H:$H,MATCH(1,(MatchHistory!$B:$B=$A39)*(MatchHistory!$H:$H<>""),0))} | N39: {=INDEX(MatchHistory!$J:$J,MATCH(1,(MatchHistory!$B:$B=$A39)*(MatchHistory!$J:$J<>""),0))}
A40: Machop | B40: =COUNTIFS(MatchHistory!$B:$B, $A40, MatchHistory!$C:$C, "Town") | C40: =COUNTIFS(MatchHistory!B:B, A40, MatchHistory!C:C, "Town", MatchHistory!D:D, "Win") | D40: =IFERROR(__xludf.DUMMYFUNCTION("TO_PERCENT($B40/$J40)"),0.75) | E40: =IFERROR(__xludf.DUMMYFUNCTION("IF(EQ($B40, 0), TO_PERCENT(0), TO_PERCENT($C40/$B40))"),0.4444444444444444) | F40: =COUNTIFS(MatchHistory!$B:$B, $A40, MatchHistory!$C:$C, "Mafia") | G40: =COUNTIFS(MatchHistory!$B:$B, $A40, MatchHistory!$C:$C, "Mafia", MatchHistory!$D:$D, "Win") | H40: =IFERROR(__xludf.DUMMYFUNCTION("TO_PERCENT($F40/$J40)"),0.25) | I40: =IFERROR(__xludf.DUMMYFUNCTION("TO_PERCENT(IFERROR($G40/$F40, 0))"),0.4444444444444444) | J40: =SUM(F40, B40) | K40: =IFERROR(__xludf.DUMMYFUNCTION("TO_PERCENT(IFERROR(($G40+$C40)/($F40+$B40), 0))"),0.4444444444444444) | L40: {=INDEX(MatchHistory!$G:$G,MATCH(1,(MatchHistory!$B:$B=$A40)*(MatchHistory!$G:$G<>""),0))} | M40: {=INDEX(MatchHistory!$H:$H,MATCH(1,(MatchHistory!$B:$B=$A40)*(MatchHistory!$H:$H<>""),0))} | N40: {=INDEX(MatchHistory!$J:$J,MATCH(1,(MatchHistory!$B:$B=$A40)*(MatchHistory!$J:$J<>""),0))}
...

Sheet MatchRatings
A1: Player | B1: mu | C1: sigma
A2: Jake | B2: 28.003534 | C2: 8.1263685
A3: Carson | B3: 28.296813 | C3: 6.3037995
A4: Creatchee | B4: 36.278695 | C4: 7.1696676
A5: Smit | B5: 24.703831 | C5: 6.3714388
A6: Boobles | B6: 28.045981 | C6: 7.8794217
A7: Badpants | B7: 26.300765 | C7: 6.2667052
A8: Kwix | B8: 21.588854 | C8: 6.4990269
A9: Chipper | B9: 28.734035 | C9: 6.5538483
A10: Machop | B10: 25.659334 | C10: 6.7882797
A11: Happymeal | B11: 22.31471 | C11: 7.5936741
A12: Lou | B12: 31.817505 | C12: 6.2562903
A13: Iln | B13: 32.195321 | C13: 6.081446
... A90: DrMorris | B90: 24.241391 | C90: 8.2767851

Sheet MatchHistory
A1: GameID | B1: Player | C1: Alignment | D1: Result | E1: RateChange | F1: old_mu | G1: new_mu | H1: new_sigma | I1: old_rating | J1: new_rating | K1: old_sigma
A2: 162 | B2: Noah | C2: Town | D2: Win | E2: 51 | F2: 33.909314 | G2: 34.60669 | H2: 6.2520663 | I2: 1665 | J2: 1716 | K2: 6.2797034
A3: 162 | B3: Badpants | C3: Town | D3: Win | E3: 50 | F3: 25.600082 | G3: 26.300765 | H3: 6.2667052 | I3: 1099 | J3: 1149 | K3: 6.2946075
A4: 162 | B4: Decode | C4: Town | D4: Win | E4: 70 | F4: 21.504604 | G4: 22.464662 | H4: 7.3202124 | I4: 711 | J4: 781 | K4: 7.3703782
A5: 162 | B5: Kden | C5: Town | D5: Win | E5: 55 | F5: 27.049288 | G5: 27.805869 | H5: 6.5089648 | I5: 1172 | J5: 1227 | K5: 6.5414217
A6: 162 | B6: Heckmuffins | C6: Town | D6: Win | E6: 79 | F6: 32.608016 | G6: 33.679836 | H6: 7.7276159 | I6: 1423 | J6: 1502 | K6: 7.7882448
A7: 162 | B7: Rocker | C7: Town | D7: Win | E7: 45 | F7: 37.986836 | G7: 38.616522 | H7: 5.9441115 | I7: 1975 | J7: 2020 | K7: 5.9664234
A8: 162 | B8: Brownkow | C8: Town | D8: Win | E8: 45 | F8: 31.436729 | G8: 32.067088 | H8: 5.9472571 | I8: 1529 | J8: 1574 | K8: 5.969621
A9: 162 | B9: Gilbert | C9: Town | D9: Win | E9: 59 | F9: 26.87935 | G9: 27.684881 | H9: 6.7135921 | I9: 1139 | J9: 1198 | K9: 6.7501481
A10: 162 | B10: Lou | C10: Town | D10: Win | E10: 50 | F10: 31.119176 | G10: 31.817505 | H10: 6.2562903 | I10: 1475 | J10: 1525 | K10: 6.2840038
A11: 162 | B11: Iln | C11: Town | D11: Win | E11: 47 | F11: 31.535889 | G11: 32.195321 | H11: 6.081446 | I11: 1522 | J11: 1569 | K11: 6.1060738
A12: 162 | B12: Chipper | C12: Mafia | D12: Loss | E12: -49 | F12: 29.501217 | G12: 28.734035 | H12: 6.5538483 | I12: 1334 | J12: 1285 | K12: 6.5871841
A13: 162 | B13: Strik3r | C13: Mafia | D13: Loss | E13: -48 | F13: 30.247833 | G13: 29.504945 | H13: 6.4504999 | I13: 1396 | J13: 1348 | K13: 6.4818286
... A1548: 46 | B1548: Lou | C1548: Mafia | D1548: Win | E1548: 58 | F1548: 25 | G1548: 25.770401 | H1548: 8.2820661 | I1548: 850 | J1548: 908 | K1548: 8.3333333

Sheet Season 1 - Stats Summary
A1: Name | B1: Town Games | C1: Town Wins | D1: Town Win % | E1: Mafia Games | F1: Mafia Wins | G1: Mafia Win % | H1: Total Win % | I1: Mu | J1: Sigma | K1: Rating
A2: Machop | B2: =COUNTIFS('Season 1 - MatchHistory'!$B:$B, $A2, 'Season 1 - MatchHistory'!$C:$C, "Town") | C2: =COUNTIFS('Season 1 - MatchHistory'!B:B, A2, 'Season 1 - MatchHistory'!C:C, "Town", 'Season 1 - MatchHistory'!D:D, "Win") | D2: =IFERROR(__xludf.DUMMYFUNCTION("IF(EQ($B2, 0), TO_PERCENT(0), TO_PERCENT($C2/$B2))"),0.47058823529411764) | E2: =COUNTIFS('Season 1 - MatchHistory'!$B:$B, $A2, 'Season 1 - MatchHistory'!$C:$C, "Mafia") | F2: =COUNTIFS('Season 1 - MatchHistory'!$B:$B, $A2, 'Season 1 - MatchHistory'!$C:$C, "Mafia", 'Season 1 - MatchHistory'!$D:$D, "Win") | G2: =IFERROR(__xludf.DUMMYFUNCTION("TO_PERCENT(IFERROR($F2/$E2, 0))"),1.0) | H2: =IFERROR(__xludf.DUMMYFUNCTION("TO_PERCENT(IFERROR(($F2+$C2)/($E2+$B2), 0))"),0.55) | I2: {=INDEX('Season 1 - MatchHistory'!$G:$G,MATCH(1,('Season 1 - MatchHistory'!$B:$B=$A2)*('Season 1 - MatchHistory'!$G:$G<>""),0))} | J2: {=INDEX('Season 1 - MatchHistory'!$H:$H,MATCH(1,('Season 1 - MatchHistory'!$B:$B=$A2)*('Season 1 - MatchHistory'!$H:$H<>""),0))} | K2: {=INDEX('Season 1 - MatchHistory'!$J:$J,MATCH(1,('Season 1 - MatchHistory'!$B:$B=$A2)*('Season 1 - MatchHistory'!$J:$J<>""),0))}
A3: Maz | B3: =COUNTIFS('Season 1 - MatchHistory'!$B:$B, $A3, 'Season 1 - MatchHistory'!$C:$C, "Town") | C3: =COUNTIFS('Season 1 - MatchHistory'!B:B, A3, 'Season 1 - MatchHistory'!C:C, "Town", 'Season 1 - MatchHistory'!D:D, "Win") | D3: =IFERROR(__xludf.DUMMYFUNCTION("IF(EQ($B3, 0), TO_PERCENT(0), TO_PERCENT($C3/$B3))"),0.4666666666666667) | E3: =COUNTIFS('Season 1 - MatchHistory'!$B:$B, $A3, 'Season 1 - MatchHistory'!$C:$C, "Mafia") | F3: =COUNTIFS('Season 1 - MatchHistory'!$B:$B, $A3, 'Season 1 - MatchHistory'!$C:$C, "Mafia", 'Season 1 - MatchHistory'!$D:$D, "Win") | G3: =IFERROR(__xludf.DUMMYFUNCTION("TO_PERCENT(IFERROR($F3/$E3, 0))"),1.0) | H3: =IFERROR(__xludf.DUMMYFUNCTION("TO_PERCENT(IFERROR(($F3+$C3)/($E3+$B3), 0))"),0.6363636363636364) | I3: {=INDEX('Season 1 - MatchHistory'!$G:$G,MATCH(1,('Season 1 - MatchHistory'!$B:$B=$A3)*('Season 1 - MatchHistory'!$G:$G<>""),0))} | J3: {=INDEX('Season 1 - MatchHistory'!$H:$H,MATCH(1,('Season 1 - MatchHistory'!$B:$B=$A3)*('Season 1 - MatchHistory'!$H:$H<>""),0))} | K3: {=INDEX('Season 1 - MatchHistory'!$J:$J,MATCH(1,('Season 1 - MatchHistory'!$B:$B=$A3)*('Season 1 - MatchHistory'!$J:$J<>""),0))}
A4: Boobles | B4: =COUNTIFS('Season 1 - MatchHistory'!$B:$B, $A4, 'Season 1 - MatchHistory'!$C:$C, "Town") | C4: =COUNTIFS('Season 1 - MatchHistory'!B:B, A4, 'Season 1 - MatchHistory'!C:C, "Town", 'Season 1 - MatchHistory'!D:D, "Win") | D4: =IFERROR(__xludf.DUMMYFUNCTION("IF(EQ($B4, 0), TO_PERCENT(0), TO_PERCENT($C4/$B4))"),0.6363636363636364) | E4: =COUNTIFS('Season 1 - MatchHistory'!$B:$B, $A4, 'Season 1 - MatchHistory'!$C:$C, "Mafia") | F4: =COUNTIFS('Season 1 - MatchHistory'!$B:$B, $A4, 'Season 1 - MatchHistory'!$C:$C, "Mafia", 'Season 1 - MatchHistory'!$D:$D, "Win") | G4: =IFERROR(__xludf.DUMMYFUNCTION("TO_PERCENT(IFERROR($F4/$E4, 0))"),1.0) | H4: =IFERROR(__xludf.DUMMYFUNCTION("TO_PERCENT(IFERROR(($F4+$C4)/($E4+$B4), 0))"),0.6666666666666666) | I4: {=INDEX('Season 1 - MatchHistory'!$G:$G,MATCH(1,('Season 1 - MatchHistory'!$B:$B=$A4)*('Season 1 - MatchHistory'!$G:$G<>""),0))} | J4: {=INDEX('Season 1 - MatchHistory'!$H:$H,MATCH(1,('Season 1 - MatchHistory'!$B:$B=$A4)*('Season 1 - MatchHistory'!$H:$H<>""),0))} | K4: {=INDEX('Season 1 - MatchHistory'!$J:$J,MATCH(1,('Season 1 - MatchHistory'!$B:$B=$A4)*('Season 1 - MatchHistory'!$J:$J<>""),0))}
A5: Noah | B5: =COUNTIFS('Season 1 - MatchHistory'!$B:$B, $A5, 'Season 1 - MatchHistory'!$C:$C, "Town") | C5: =COUNTIFS('Season 1 - MatchHistory'!B:B, A5, 'Season 1 - MatchHistory'!C:C, "Town", 'Season 1 - MatchHistory'!D:D, "Win") | D5: =IFERROR(__xludf.DUMMYFUNCTION("IF(EQ($B5, 0), TO_PERCENT(0), TO_PERCENT($C5/$B5))"),0.4230769230769231) | E5: =COUNTIFS('Season 1 - MatchHistory'!$B:$B, $A5, 'Season 1 - MatchHistory'!$C:$C, "Mafia") | F5: =COUNTIFS('Season 1 - MatchHistory'!$B:$B, $A5, 'Season 1 - MatchHistory'!$C:$C, "Mafia", 'Season 1 - MatchHistory'!$D:$D, "Win") | G5: =IFERROR(__xludf.DUMMYFUNCTION("TO_PERCENT(IFERROR($F5/$E5, 0))"),0.8333333333333334) | H5: =IFERROR(__xludf.DUMMYFUNCTION("TO_PERCENT(IFERROR(($F5+$C5)/($E5+$B5), 0))"),0.5526315789473685) | I5: {=INDEX('Season 1 - MatchHistory'!$G:$G,MATCH(1,('Season 1 - MatchHistory'!$B:$B=$A5)*('Season 1 - MatchHistory'!$G:$G<>""),0))} | J5: {=INDEX('Season 1 - MatchHistory'!$H:$H,MATCH(1,('Season 1 - MatchHistory'!$B:$B=$A5)*('Season 1 - MatchHistory'!$H:$H<>""),0))} | K5: {=INDEX('Season 1 - MatchHistory'!$J:$J,MATCH(1,('Season 1 - MatchHistory'!$B:$B=$A5)*('Season 1 - MatchHistory'!$J:$J<>""),0))}
A6: Rick | B6: =COUNTIFS('Season 1 - MatchHistory'!$B:$B, $A6, 'Season 1 - MatchHistory'!$C:$C, "Town") | C6: =COUNTIFS('Season 1 - MatchHistory'!B:B, A6, 'Season 1 - MatchHistory'!C:C, "Town", 'Season 1 - MatchHistory'!D:D, "Win") | D6: =IFERROR(__xludf.DUMMYFUNCTION("IF(EQ($B6, 0), TO_PERCENT(0), TO_PERCENT($C6/$B6))"),0.8) | E6: =COUNTIFS('Season 1 - MatchHistory'!$B:$B, $A6, 'Season 1 - MatchHistory'!$C:$C, "Mafia") | F6: =COUNTIFS('Season 1 - MatchHistory'!$B:$B, $A6, 'Season 1 - MatchHistory'!$C:$C, "Mafia", 'Season 1 - MatchHistory'!$D:$D, "Win") | G6: =IFERROR(__xludf.DUMMYFUNCTION("TO_PERCENT(IFERROR($F6/$E6, 0))"),1.0) | H6: =IFERROR(__xludf.DUMMYFUNCTION("TO_PERCENT(IFERROR(($F6+$C6)/($E6+$B6), 0))"),0.8333333333333334) | I6: {=INDEX('Season 1 - MatchHistory'!$G:$G,MATCH(1,('Season 1 - MatchHistory'!$B:$B=$A6)*('Season 1 - MatchHistory'!$G:$G<>""),0))} | J6: {=INDEX('Season 1 - MatchHistory'!$H:$H,MATCH(1,('Season 1 - MatchHistory'!$B:$B=$A6)*('Season 1 - MatchHistory'!$H:$H<>""),0))} | K6: {=INDEX('Season 1 - MatchHistory'!$J:$J,MATCH(1,('Season 1 - MatchHistory'!$B:$B=$A6)*('Season 1 - MatchHistory'!$J:$J<>""),0))}
A7: Keegan | B7: =COUNTIFS('Season 1 - MatchHistory'!$B:$B, $A7, 'Season 1 - MatchHistory'!$C:$C, "Town") | C7: =COUNTIFS('Season 1 - MatchHistory'!B:B, A7, 'Season 1 - MatchHistory'!C:C, "Town", 'Season 1 - MatchHistory'!D:D, "Win") | D7: =IFERROR(__xludf.DUMMYFUNCTION("IF(EQ($B7, 0), TO_PERCENT(0), TO_PERCENT($C7/$B7))"),0.4666666666666667) | E7: =COUNTIFS('Season 1 - MatchHistory'!$B:$B, $A7, 'Season 1 - MatchHistory'!$C:$C, "Mafia") | F7: =COUNTIFS('Season 1 - MatchHistory'!$B:$B, $A7, 'Season 1 - MatchHistory'!$C:$C, "Mafia", 'Season 1 - MatchHistory'!$D:$D, "Win") | G7: =IFERROR(__xludf.DUMMYFUNCTION("TO_PERCENT(IFERROR($F7/$E7, 0))"),1.0) | H7: =IFERROR(__xludf.DUMMYFUNCTION("TO_PERCENT(IFERROR(($F7+$C7)/($E7+$B7), 0))"),0.5294117647058824) | I7: {=INDEX('Season 1 - MatchHistory'!$G:$G,MATCH(1,('Season 1 - MatchHistory'!$B:$B=$A7)*('Season 1 - MatchHistory'!$G:$G<>""),0))} | J7: {=INDEX('Season 1 - MatchHistory'!$H:$H,MATCH(1,('Season 1 - MatchHistory'!$B:$B=$A7)*('Season 1 - MatchHistory'!$H:$H<>""),0))} | K7: {=INDEX('Season 1 - MatchHistory'!$J:$J,MATCH(1,('Season 1 - MatchHistory'!$B:$B=$A7)*('Season 1 - MatchHistory'!$J:$J<>""),0))}
A8: Mintt | B8: =COUNTIFS('Season 1 - MatchHistory'!$B:$B, $A8, 'Season 1 - MatchHistory'!$C:$C, "Town") | C8: =COUNTIFS('Season 1 - MatchHistory'!B:B, A8, 'Season 1 - MatchHistory'!C:C, "Town", 'Season 1 - MatchHistory'!D:D, "Win") | D8: =IFERROR(__xludf.DUMMYFUNCTION("IF(EQ($B8, 0), TO_PERCENT(0), TO_PERCENT($C8/$B8))"),0.75) | E8: =COUNTIFS('Season 1 - MatchHistory'!$B:$B, $A8, 'Season 1 - MatchHistory'!$C:$C, "Mafia") | F8: =COUNTIFS('Season 1 - MatchHistory'!$B:$B, $A8, 'Season 1 - MatchHistory'!$C:$C, "Mafia", 'Season 1 - MatchHistory'!$D:$D, "Win") | G8: =IFERROR(__xludf.DUMMYFUNCTION("TO_PERCENT(IFERROR($F8/$E8, 0))"),1.0) | H8: =IFERROR(__xludf.DUMMYFUNCTION("TO_PERCENT(IFERROR(($F8+$C8)/($E8+$B8), 0))"),0.8) | I8: {=INDEX('Season 1 - MatchHistory'!$G:$G,MATCH(1,('Season 1 - MatchHistory'!$B:$B=$A8)*('Season 1 - MatchHistory'!$G:$G<>""),0))} | J8: {=INDEX('Season 1 - MatchHistory'!$H:$H,MATCH(1,('Season 1 - MatchHistory'!$B:$B=$A8)*('Season 1 - MatchHistory'!$H:$H<>""),0))} | K8: {=INDEX('Season 1 - MatchHistory'!$J:$J,MATCH(1,('Season 1 - MatchHistory'!$B:$B=$A8)*('Season 1 - MatchHistory'!$J:$J<>""),0))}
A9: Badpants | B9: =COUNTIFS('Season 1 - MatchHistory'!$B:$B, $A9, 'Season 1 - MatchHistory'!$C:$C, "Town") | C9: =COUNTIFS('Season 1 - MatchHistory'!B:B, A9, 'Season 1 - MatchHistory'!C:C, "Town", 'Season 1 - MatchHistory'!D:D, "Win") | D9: =IFERROR(__xludf.DUMMYFUNCTION("IF(EQ($B9, 0), TO_PERCENT(0), TO_PERCENT($C9/$B9))"),1.0) | E9: =COUNTIFS('Season 1 - MatchHistory'!$B:$B, $A9, 'Season 1 - MatchHistory'!$C:$C, "Mafia") | F9: =COUNTIFS('Season 1 - MatchHistory'!$B:$B, $A9, 'Season 1 - MatchHistory'!$C:$C, "Mafia", 'Season 1 - MatchHistory'!$D:$D, "Win") | G9: =IFERROR(__xludf.DUMMYFUNCTION("TO_PERCENT(IFERROR($F9/$E9, 0))"),0.6666666666666666) | H9: =IFERROR(__xludf.DUMMYFUNCTION("TO_PERCENT(IFERROR(($F9+$C9)/($E9+$B9), 0))"),0.8) | I9: {=INDEX('Season 1 - MatchHistory'!$G:$G,MATCH(1,('Season 1 - MatchHistory'!$B:$B=$A9)*('Season 1 - MatchHistory'!$G:$G<>""),0))} | J9: {=INDEX('Season 1 - MatchHistory'!$H:$H,MATCH(1,('Season 1 - MatchHistory'!$B:$B=$A9)*('Season 1 - MatchHistory'!$H:$H<>""),0))} | K9: {=INDEX('Season 1 - MatchHistory'!$J:$J,MATCH(1,('Season 1 - MatchHistory'!$B:$B=$A9)*('Season 1 - MatchHistory'!$J:$J<>""),0))}
A10: Xcync | B10: =COUNTIFS('Season 1 - MatchHistory'!$B:$B, $A10, 'Season 1 - MatchHistory'!$C:$C, "Town") | C10: =COUNTIFS('Season 1 - MatchHistory'!B:B, A10, 'Season 1 - MatchHistory'!C:C, "Town", 'Season 1 - MatchHistory'!D:D, "Win") | D10: =IFERROR(__xludf.DUMMYFUNCTION("IF(EQ($B10, 0), TO_PERCENT(0), TO_PERCENT($C10/$B10))"),0.6666666666666666) | E10: =COUNTIFS('Season 1 - MatchHistory'!$B:$B, $A10, 'Season 1 - MatchHistory'!$C:$C, "Mafia") | F10: =COUNTIFS('Season 1 - MatchHistory'!$B:$B, $A10, 'Season 1 - MatchHistory'!$C:$C, "Mafia", 'Season 1 - MatchHistory'!$D:$D, "Win") | G10: =IFERROR(__xludf.DUMMYFUNCTION("TO_PERCENT(IFERROR($F10/$E10, 0))"),0.0) | H10: =IFERROR(__xludf.DUMMYFUNCTION("TO_PERCENT(IFERROR(($F10+$C10)/($E10+$B10), 0))"),0.5714285714285714) | I10: {=INDEX('Season 1 - MatchHistory'!$G:$G,MATCH(1,('Season 1 - MatchHistory'!$B:$B=$A10)*('Season 1 - MatchHistory'!$G:$G<>""),0))} | J10: {=INDEX('Season 1 - MatchHistory'!$H:$H,MATCH(1,('Season 1 - MatchHistory'!$B:$B=$A10)*('Season 1 - MatchHistory'!$H:$H<>""),0))} | K10: {=INDEX('Season 1 - MatchHistory'!$J:$J,MATCH(1,('Season 1 - MatchHistory'!$B:$B=$A10)*('Season 1 - MatchHistory'!$J:$J<>""),0))}
A11: Aipha | B11: =COUNTIFS('Season 1 - MatchHistory'!$B:$B, $A11, 'Season 1 - MatchHistory'!$C:$C, "Town") | C11: =COUNTIFS('Season 1 - MatchHistory'!B:B, A11, 'Season 1 - MatchHistory'!C:C, "Town", 'Season 1 - MatchHistory'!D:D, "Win") | D11: =IFERROR(__xludf.DUMMYFUNCTION("IF(EQ($B11, 0), TO_PERCENT(0), TO_PERCENT($C11/$B11))"),1.0) | E11: =COUNTIFS('Season 1 - MatchHistory'!$B:$B, $A11, 'Season 1 - MatchHistory'!$C:$C, "Mafia") | F11: =COUNTIFS('Season 1 - MatchHistory'!$B:$B, $A11, 'Season 1 - MatchHistory'!$C:$C, "Mafia", 'Season 1 - MatchHistory'!$D:$D, "Win") | G11: =IFERROR(__xludf.DUMMYFUNCTION("TO_PERCENT(IFERROR($F11/$E11, 0))"),1.0) | H11: =IFERROR(__xludf.DUMMYFUNCTION("TO_PERCENT(IFERROR(($F11+$C11)/($E11+$B11), 0))"),1.0) | I11: {=INDEX('Season 1 - MatchHistory'!$G:$G,MATCH(1,('Season 1 - MatchHistory'!$B:$B=$A11)*('Season 1 - MatchHistory'!$G:$G<>""),0))} | J11: {=INDEX('Season 1 - MatchHistory'!$H:$H,MATCH(1,('Season 1 - MatchHistory'!$B:$B=$A11)*('Season 1 - MatchHistory'!$H:$H<>""),0))} | K11: {=INDEX('Season 1 - MatchHistory'!$J:$J,MATCH(1,('Season 1 - MatchHistory'!$B:$B=$A11)*('Season 1 - MatchHistory'!$J:$J<>""),0))}
A12: Motr | B12: =COUNTIFS('Season 1 - MatchHistory'!$B:$B, $A12, 'Season 1 - MatchHistory'!$C:$C, "Town") | C12: =COUNTIFS('Season 1 - MatchHistory'!B:B, A12, 'Season 1 - MatchHistory'!C:C, "Town", 'Season 1 - MatchHistory'!D:D, "Win") | D12: =IFERROR(__xludf.DUMMYFUNCTION("IF(EQ($B12, 0), TO_PERCENT(0), TO_PERCENT($C12/$B12))"),0.75) | E12: =COUNTIFS('Season 1 - MatchHistory'!$B:$B, $A12, 'Season 1 - MatchHistory'!$C:$C, "Mafia") | F12: =COUNTIFS('Season 1 - MatchHistory'!$B:$B, $A12, 'Season 1 - MatchHistory'!$C:$C, "Mafia", 'Season 1 - MatchHistory'!$D:$D, "Win") | G12: =IFERROR(__xludf.DUMMYFUNCTION("TO_PERCENT(IFERROR($F12/$E12, 0))"),0.5) | H12: =IFERROR(__xludf.DUMMYFUNCTION("TO_PERCENT(IFERROR(($F12+$C12)/($E12+$B12), 0))"),0.6666666666666666) | I12: {=INDEX('Season 1 - MatchHistory'!$G:$G,MATCH(1,('Season 1 - MatchHistory'!$B:$B=$A12)*('Season 1 - MatchHistory'!$G:$G<>""),0))} | J12: {=INDEX('Season 1 - MatchHistory'!$H:$H,MATCH(1,('Season 1 - MatchHistory'!$B:$B=$A12)*('Season 1 - MatchHistory'!$H:$H<>""),0))} | K12: {=INDEX('Season 1 - MatchHistory'!$J:$J,MATCH(1,('Season 1 - MatchHistory'!$B:$B=$A12)*('Season 1 - MatchHistory'!$J:$J<>""),0))}
